<?xml version="1.0"?>
<robot name="Cube">

<link name="world"/>
<link name="cubee">
    <visual>
        <geometry>
            <box size="0.1 0.1 0.1"/>
        </geometry>
        <!-- <material name="kk">
            <color rgba="0.8 0.3 0.3 1"/>
        </material> -->
    </visual>
    <collision>
        <geometry>
            <box size="0.1 0.1 0.1"/>
        </geometry>
    </collision>
    <inertial>
        <mass value="0.2"/>
        <inertia ixx="0.00035" ixy="0" ixz="0" iyy="0.00035" iyz="0" izz="0.00035"/>
    </inertial>
</link>

<joint name="cube_plane_joint" type="floating">
    <parent link="world"/>
    <child link="cubee"/>
    <origin xyz="0 0 0.1" rpy="0 0 0"/>
</joint>
</robot>