<?xml version="1.0" ?>
<robot xmlns:xacro="http://www.ros.org/wiki/xacro">

  <!--
    rizon_type = "rizon4", "rizon4s"
    prefix = "", "left_"
    mesh_prefix_path = "", "package://flexiv_description/"
    NOTE: accurate kinematic but approximated dynamics parameters
  -->
  <xacro:macro name="rizon4_joints_links" params="rizon_type prefix mesh_prefix_path">

    <!-- JOINTS-->
    <joint name="${prefix}base_joint" type="fixed">
      <parent link="world"/>
      <child link="${prefix}base_link" />
      <origin xyz="0.0 0.0 0.0" rpy="0.0 0.0 0.0"/>
    </joint>

    <joint name="${prefix}joint1" type="revolute">
      <parent link="${prefix}base_link"/>
      <child link="${prefix}link1"/>
      <origin xyz="0.0 0.0 0.155" rpy="0 0 ${-pi}"/>
      <axis xyz="0 0 1"/>
      <limit effort="123" lower="-2.7925" upper="2.7925" velocity="2.0944"/>
    </joint>

    <joint name="${prefix}joint2" type="revolute">
      <parent link="${prefix}link1"/>
      <child link="${prefix}link2"/>
      <origin xyz="0.0 0.03 0.210" rpy="0 0 0"/>
      <axis xyz="0 1 0"/>
      <limit effort="123" lower="-2.2689" upper="2.2689" velocity="2.0944"/>
    </joint>

    <joint name="${prefix}joint3" type="revolute">
      <parent link="${prefix}link2"/>
      <child link="${prefix}link3"/>
      <origin xyz="0.0 0.035 0.205" rpy="0 0 0"/>
      <axis xyz="0 0 1"/>
      <limit effort="64" lower="-2.9671" upper="2.9671" velocity="2.4435"/>
    </joint>

    <joint name="${prefix}joint4" type="revolute">
      <parent link="${prefix}link3"/>
      <child link="${prefix}link4"/>
      <origin xyz="-0.02 -0.03 0.19" rpy="0 0 ${-pi}"/>
      <axis xyz="0 1 0"/>
      <limit effort="64" lower="-1.8675" upper="2.6878" velocity="2.4435" />
    </joint>

    <joint name="${prefix}joint5" type="revolute">
      <parent link="${prefix}link4"/>
      <child link="${prefix}link5"/>
      <origin xyz="-0.02 0.025 0.195" rpy="0 0 ${-pi}"/>
      <axis xyz="0 0 1"/>
      <limit effort="39" lower="-2.9671" upper="2.9671" velocity="4.8869" />
    </joint>

    <joint name="${prefix}joint6" type="revolute">
      <parent link="${prefix}link5"/>
      <child link="${prefix}link6"/>
      <origin xyz="0.0 0.03 0.19" rpy="0 0 0"/>
      <axis xyz="0 1 0"/>
      <limit effort="39" lower="-1.3963" upper="4.5379" velocity="4.8869" />
    </joint>

    <joint name="${prefix}joint7" type="revolute">
      <parent link="${prefix}link6"/>
      <child link="${prefix}link7"/>
      <origin xyz="-0.055 0.070 0.11" rpy="0 ${-pi/2} 0"/>
      <axis xyz="0 0 1"/>
      <limit effort="39" lower="-2.9671" upper="2.9671" velocity="4.8869" />
    </joint>

    <joint name="${prefix}link7_to_flange" type="fixed">
      <parent link="${prefix}link7"/>
      <child link="${prefix}flange"/>
      <xacro:if value="${rizon_type=='rizon4'}">
        <origin xyz="0.0 0.0 0.081" rpy="0 0 ${-pi}"/>
      </xacro:if>
      <xacro:if value="${rizon_type=='rizon4s'}">
        <origin xyz="0.0 0.0 0.124" rpy="0 0 ${-pi}"/>
      </xacro:if>
    </joint>

    <!-- LINKS -->
    <link name="world">
    </link>

    <link name="${prefix}base_link">
      <inertial>
        <mass value="3.7" />
        <origin rpy="0 0 0" xyz="0.0 -0.0 0.09" />
        <inertia ixx="0.02" ixy="0.0" ixz="0.0" iyy="0.02" iyz="0.0" izz="0.01" />
      </inertial>
      <visual>
        <origin xyz="0 0 0" rpy="0 0 0"/>
        <geometry>
          <mesh filename="${mesh_prefix_path}meshes/${rizon_type}/visual/link0.obj" />
        </geometry>
        <material name="rizon_light_grey" />
      </visual>
      <collision>
        <origin xyz="0 0 0" rpy="0 0 0"/>
        <geometry>
          <mesh filename="${mesh_prefix_path}meshes/${rizon_type}/collision/link0.stl" />
        </geometry>
      </collision>
    </link>

    <link name="${prefix}link1">
      <inertial>
        <mass value="3.7" />
        <origin rpy="0 0 0" xyz="0.0 0.01 0.15" />
        <inertia ixx="0.03" ixy="0.0" ixz="0.0" iyy="0.03" iyz="0.0" izz="0.01" />
      </inertial>
      <visual>
        <origin xyz="0 0 0" rpy="0 0 0" />
        <geometry>
          <mesh filename="${mesh_prefix_path}meshes/${rizon_type}/visual/link1.obj" />
        </geometry>
        <material name="rizon_light_grey" />
      </visual>
      <collision>
        <origin xyz="0 0 0" rpy="0 0 0" />
        <geometry>
          <mesh filename="${mesh_prefix_path}meshes/${rizon_type}/collision/link1.stl" />
        </geometry>
      </collision>
    </link>

    <link name="${prefix}link2">
      <inertial>
        <mass value="2.7" />
        <origin rpy="0 0 0" xyz="0.0 0.04 0.1" />
        <inertia ixx="0.02" ixy="0.0" ixz="0.0" iyy="0.02" iyz="-0.0" izz="0.0" />
      </inertial>
      <visual>
        <origin xyz="0 0 0" rpy="0 0 0"/>
        <geometry>
          <mesh filename="${mesh_prefix_path}meshes/${rizon_type}/visual/link2.obj" />
        </geometry>
        <material name="rizon_light_grey" />
      </visual>
      <collision>
        <origin xyz="0 0 0" rpy="0 0 0"/>
        <geometry>
          <mesh filename="${mesh_prefix_path}meshes/${rizon_type}/collision/link2.stl" />
        </geometry>
      </collision>
    </link>

    <link name="${prefix}link3">
      <inertial>
        <mass value="2.4" />
        <origin rpy="0 0 0" xyz="-0.01 -0.0 0.13" />
        <inertia ixx="0.01" ixy="0.0" ixz="-0.0" iyy="0.01" iyz="-0.0" izz="0.0" />
      </inertial>
      <visual>
        <origin xyz="0 0 0" rpy="0 0 0" />
        <geometry>
          <mesh filename="${mesh_prefix_path}meshes/${rizon_type}/visual/link3.obj" />
        </geometry>
        <material name="rizon_light_grey" />
      </visual>
      <collision>
        <origin xyz="0 0 0" rpy="0 0 0" />
        <geometry>
          <mesh filename="${mesh_prefix_path}meshes/${rizon_type}/collision/link3.stl" />
        </geometry>
      </collision>
    </link>

    <link name="${prefix}link4">
      <inertial>
        <mass value="2.4" />
        <origin rpy="0 0 0" xyz="-0.01 0.03 0.1" />
        <inertia ixx="0.02" ixy="0.0" ixz="-0.0" iyy="0.02" iyz="-0.0" izz="0.0" />
      </inertial>
      <visual>
        <origin xyz="0 0 0" rpy="0 0 0"/>
        <geometry>
          <mesh filename="${mesh_prefix_path}meshes/${rizon_type}/visual/link4.obj" />
        </geometry>
        <material name="rizon_light_grey" />
      </visual>
      <collision>
        <origin xyz="0 0 0" rpy="0 0 0"/>
        <geometry>
          <mesh filename="${mesh_prefix_path}meshes/${rizon_type}/collision/link4.stl" />
        </geometry>
      </collision>
    </link>

    <link name="${prefix}link5">
      <inertial>
        <mass value="2.4" />
        <origin rpy="0 0 0" xyz="0.0 0.0 0.13" />
        <inertia ixx="0.01" ixy="0.0" ixz="0.0" iyy="0.01" iyz="0.0" izz="0.0" />
      </inertial>
      <visual>
        <origin xyz="0 0 0" rpy="0 0 0"/>
        <geometry>
          <mesh filename="${mesh_prefix_path}meshes/${rizon_type}/visual/link5.obj" />
        </geometry>
        <material name="rizon_light_grey" />
      </visual>
      <collision>
        <origin xyz="0 0 0" rpy="0 0 0"/>
        <geometry>
          <mesh filename="${mesh_prefix_path}meshes/${rizon_type}/collision/link5.stl" />
        </geometry>
      </collision>
    </link>

    <link name="${prefix}link6">
      <inertial>
        <mass value="2.1" />
        <origin rpy="0 0 0" xyz="-0.01 0.06 0.07" />
        <inertia ixx="0.01" ixy="-0.0" ixz="-0.001" iyy="0.01" iyz="0.0" izz="0.0" />
      </inertial>
      <visual>
        <origin xyz="0 0 0" rpy="0 0 0"/>
        <geometry>
          <mesh filename="${mesh_prefix_path}meshes/${rizon_type}/visual/link6.obj" />
        </geometry>
        <material name="rizon_light_grey" />
      </visual>
      <collision>
        <origin xyz="0 0 0" rpy="0 0 0"/>
        <geometry>
          <mesh filename="${mesh_prefix_path}meshes/${rizon_type}/collision/link6.stl" />
        </geometry>
      </collision>
    </link>

    <link name="${prefix}link7">
      <xacro:if value="${rizon_type=='rizon4'}">
        <inertial>
          <mass value="0.8" />
          <origin rpy="0 0 0" xyz="0.0 0.0 0.03" />
          <inertia ixx="0.0" ixy="0.0" ixz="0.0" iyy="0.0" iyz="0.0" izz="0.0" />
        </inertial>
        <visual>
          <origin xyz="0 0 0" rpy="0 0 0"/>
          <geometry>
            <mesh filename="${mesh_prefix_path}meshes/${rizon_type}/visual/link7.obj" />
          </geometry>
          <material name="rizon_light_grey" />
        </visual>
        <collision>
          <origin xyz="0 0 0" rpy="0 0 0"/>
          <geometry>
            <mesh filename="${mesh_prefix_path}meshes/${rizon_type}/collision/link7.stl" />
          </geometry>
        </collision>
      </xacro:if>
      <xacro:if value="${rizon_type=='rizon4s'}">
        <inertial>
          <mass value="1.4" />
          <origin xyz="0.0 0.0 0.05" rpy="0 0 0"/>
          <inertia ixx="0.0" iyy="0.0" izz="0.0" ixy="0.0" ixz="0.0" iyz="0.0"/>
        </inertial>
        <visual>
          <origin xyz="0 0 0" rpy="0 0 0"/>
          <geometry>
            <mesh filename="${mesh_prefix_path}meshes/${rizon_type}/visual/link7.obj" />
          </geometry>
          <material name="rizon_light_grey" />
        </visual>
        <collision>
          <origin xyz="0 0 0" rpy="0 0 0"/>
          <geometry>
            <mesh filename="${mesh_prefix_path}meshes/${rizon_type}/collision/link7.stl" />
          </geometry>
        </collision>
      </xacro:if>
    </link>

    <link name="${prefix}flange"/>

          
    <!-- 继承grav的xacro -->
    <!-- <xacro:include filename="$(find flexiv_description)/urdf/grav.xacro"/> -->

    <joint name="rizon_grav_joint" type="fixed">
      <parent link="${prefix}flange"/>
      <child link="grav_base_link"/>
      <origin xyz="0 0 0" rpy="0 0 0"/>
    </joint>
      
    <!-- <xacro:grav 
      rizon_type="${arg rizon_type}"
      prefix="${arg prefix}"
    />  -->
    <link name="grav_base_link">
        <inertial>
        <origin rpy="0 0 0" xyz="0 0 0.057"/>
        <mass value="1.186"/>
        <inertia ixx="3E-3" ixy="0" ixz="0" iyy="3E-3" iyz="-0" izz="1E-3"/>
        </inertial>
        <visual>
        <origin rpy="0 0 1.5707963267948966" xyz="0 0 0"/>
        <geometry>
            <mesh filename="${mesh_prefix_path}meshes/grav/visual/base.stl" scale="0.001 0.001 0.001"/>
        </geometry>
        <material name="flexiv_black"/>
        </visual>
        <collision>
        <origin rpy="0 0 1.5707963267948966" xyz="0 0 0"/>
        <geometry>
            <mesh filename="${mesh_prefix_path}meshes/grav/collision/base.stl" scale="0.001 0.001 0.001"/>
        </geometry>
        </collision>
    </link>

    <!-- left finger links -->
    <link name="left_outer_bar">
        <inertial>
            <origin xyz="0 0 0.029" rpy="0 0 0" />
            <mass value="1E-4" />
            <inertia ixx="1E-7" ixy="0" ixz="0" iyy="1E-7" iyz="0" izz="1E-7" />
        </inertial>
        <visual>
        <origin rpy="0 0 1.5707963267948966" xyz="0 0 0"/>
        <geometry>
            <mesh filename="${mesh_prefix_path}meshes/grav/visual/outer_bar.stl" scale="0.001 0.001 0.001"/>
        </geometry>
        <material name="flexiv_black"/>
        </visual>
    </link>
    <link name="left_inner_bar">
        <inertial>
            <origin xyz="0 0 0.029" rpy="0 0 0" />
        <mass value="1E-4" />
            <inertia ixx="1E-7" ixy="0" ixz="0" iyy="1E-7" iyz="0" izz="1E-7" />
        </inertial>
        <visual>
        <origin rpy="0 0 1.5707963267948966" xyz="0 0 0"/>
        <geometry>
            <mesh filename="${mesh_prefix_path}meshes/grav/visual/inner_bar.stl" scale="0.001 0.001 0.001"/>
        </geometry>
        <material name="flexiv_black"/>
        </visual>
    </link>
    <link name="left_finger_mount">
        <inertial>
            <origin xyz="0 0 0" rpy="0 0 0" />
            <mass value="1E-4" />
            <inertia ixx="1E-7" ixy="0" ixz="0" iyy="1E-7" iyz="0" izz="1E-7" />
        </inertial>
        <visual>
        <origin rpy="0 0 1.5707963267948966" xyz="0 0 0"/>
        <geometry>
            <mesh filename="${mesh_prefix_path}meshes/grav/visual/finger_mount.stl" scale="0.001 0.001 0.001"/>
        </geometry>
        <material name="flexiv_black"/>
        </visual>
    </link>
    <link name="left_finger_tip">
        <inertial>
        <origin rpy="0 0 0" xyz="0 0 0"/>
        <mass value="0"/>
        <inertia ixx="0" ixy="0" ixz="0" iyy="0" iyz="0" izz="0"/>
        </inertial>
        <visual>
        <origin rpy="0 0 1.5707963267948966" xyz="0 0 0"/>
        <geometry>
            <mesh filename="${mesh_prefix_path}meshes/grav/visual/finger_tip.obj" scale="0.001 0.001 0.001"/>
        </geometry>
        </visual>
        <collision>
        <origin rpy="0 0 1.5707963267948966" xyz="0 0 0"/>
        <geometry>
            <mesh filename="${mesh_prefix_path}meshes/grav/collision/finger_tip.stl" scale="0.001 0.001 0.001"/>
        </geometry>
        </collision>
    </link>

    <!-- right finger links -->
    <link name="right_outer_bar">
        <inertial>
            <origin xyz="0 0 0.029" rpy="0 0 0" />
            <mass value="1E-4" />
            <inertia ixx="1E-7" ixy="0" ixz="0" iyy="1E-7" iyz="0" izz="1E-7" />
        </inertial>
        <visual>
        <origin rpy="0 0 1.5707963267948966" xyz="0 0 0"/>
        <geometry>
            <mesh filename="${mesh_prefix_path}meshes/grav/visual/outer_bar.stl" scale="0.001 0.001 0.001"/>
        </geometry>
        <material name="flexiv_black"/>
        </visual>
    </link>
    <link name="right_inner_bar">
        <inertial>
            <origin xyz="0 0 0.029" rpy="0 0 0" />
            <mass value="1E-4" />
            <inertia ixx="1E-7" ixy="0" ixz="0" iyy="1E-7" iyz="0" izz="1E-7" />
        </inertial>
        <visual>
        <origin rpy="0 0 1.5707963267948966" xyz="0 0 0"/>
        <geometry>
            <mesh filename="${mesh_prefix_path}meshes/grav/visual/inner_bar.stl" scale="0.001 0.001 0.001"/>
        </geometry>
        <material name="flexiv_black"/>
        </visual>
    </link>
    <link name="right_finger_mount">
        <inertial>
            <origin xyz="0 0 0" rpy="0 0 0" />
            <mass value="1E-4" />
            <inertia ixx="1E-7" ixy="0" ixz="0" iyy="1E-7" iyz="0" izz="1E-7" />
        </inertial>
        <visual>
        <origin rpy="0 0 1.5707963267948966" xyz="0 0 0"/>
        <geometry>
            <mesh filename="${mesh_prefix_path}meshes/grav/visual/finger_mount.stl" scale="0.001 0.001 0.001"/>
        </geometry>
        <material name="flexiv_black"/>
        </visual>
    </link>
    <link name="right_finger_tip">
        <inertial>
        <origin rpy="0 0 0" xyz="0 0 0"/>
        <mass value="0"/>
        <inertia ixx="0" ixy="0" ixz="0" iyy="0" iyz="0" izz="0"/>
        </inertial>
        <visual>
        <origin rpy="0 0 1.5707963267948966" xyz="0 0 0"/>
        <geometry>
            <mesh filename="${mesh_prefix_path}meshes/grav/visual/finger_tip.obj" scale="0.001 0.001 0.001"/>
        </geometry>
        </visual>
        <collision>
        <origin rpy="0 0 1.5707963267948966" xyz="0 0 0"/>
        <geometry>
            <mesh filename="${mesh_prefix_path}meshes/grav/collision/finger_tip.stl" scale="0.001 0.001 0.001"/>
        </geometry>
        </collision>
    </link>

    <!-- TCP links -->
    <link name="tcp"><!-- open finger, used by RCA -->
        <inertial>
        <origin rpy="0 0 0" xyz="0 0 0"/>
        <mass value="0"/>
        <inertia ixx="0" ixy="0" ixz="0" iyy="0" iyz="0" izz="0"/>
        </inertial>
    </link>
    <link name="closed_fingers_tcp">
        <inertial>
        <origin rpy="0 0 0" xyz="0 0 0"/>
        <mass value="0"/>
        <inertia ixx="0" ixy="0" ixz="0" iyy="0" iyz="0" izz="0"/>
        </inertial>
    </link>
    <link name="left_finger_tcp">
        <inertial>
        <origin rpy="0 0 0" xyz="0 0 0"/>
        <mass value="0"/>
        <inertia ixx="0" ixy="0" ixz="0" iyy="0" iyz="0" izz="0"/>
        </inertial>
    </link>
    <link name="right_finger_tcp">
        <inertial>
        <origin rpy="0 0 0" xyz="0 0 0"/>
        <mass value="0"/>
        <inertia ixx="0" ixy="0" ixz="0" iyy="0" iyz="0" izz="0"/>
        </inertial>
    </link>

    <joint name="open_fingers_tcp_joint" type="fixed">
        <origin rpy="0 0 0" xyz="0 0 0.15"/>
        <parent link="grav_base_link"/>
        <child link="tcp"/>
        <axis xyz="0 0 1"/>
    </joint>

    <joint name="closed_fingers_tcp_joint" type="fixed">
        <origin rpy="0 0 0" xyz="0 0 0.20"/>
        <parent link="grav_base_link"/>
        <child link="closed_fingers_tcp"/>
        <axis xyz="0 0 1"/>
    </joint>

    <!-- left finger joints -->
    <joint name="left_outer_knuckle_joint" type="revolute">
        <origin rpy="0 0 0" xyz="0 -0.0325 0.0825"/>
        <parent link="grav_base_link"/>
        <child link="left_outer_bar"/>
        <axis xyz="1 0 0"/>
        <limit effort="0" lower="-0.155" upper="0.7854" velocity="2.0"/>
        <mimic joint="finger_width_joint" multiplier="9.404" offset="-0.155"/>
    </joint>
    <joint name="left_inner_knuckle_joint" type="revolute">
        <origin rpy="0 0 0" xyz="0 -0.0165 0.0995"/>
        <parent link="grav_base_link"/>
        <child link="left_inner_bar"/>
        <axis xyz="1 0 0"/>
        <limit effort="0" lower="-0.155" upper="0.7854" velocity="2.0"/>
        <mimic joint="left_outer_knuckle_joint" multiplier="1" offset="0"/>
    </joint>
    <joint name="left_inner_finger_joint" type="revolute">
        <origin rpy="0 0 0" xyz="0 0 0.058"/>
        <parent link="left_outer_bar"/>
        <child link="left_finger_mount"/>
        <axis xyz="1 0 0"/>
        <limit effort="0" lower="-0.7854" upper="0.155" velocity="2.0"/>
        <mimic joint="left_outer_knuckle_joint" multiplier="-1" offset="0"/>
    </joint>
    <joint name="left_inner_finger_pad_joint" type="fixed">
        <origin rpy="0 0 0" xyz="0 0.010 0.0235"/>
        <parent link="left_finger_mount"/>
        <child link="left_finger_tip"/>
        <axis xyz="0 0 1"/>
    </joint>
    <joint name="left_finger_tcp_joint" type="fixed">
        <origin rpy="0 0 0" xyz="0 0.0135 0.036"/>
        <parent link="left_finger_tip"/>
        <child link="left_finger_tcp"/>
        <axis xyz="0 0 1"/>
    </joint>

    <!-- right finger joints -->
    <joint name="right_outer_knuckle_joint" type="revolute">
        <origin rpy="0 0 3.141592653589793" xyz="0 0.0325 0.0825"/>
        <parent link="grav_base_link"/>
        <child link="right_outer_bar"/>
        <axis xyz="1 0 0"/>
        <limit effort="0" lower="-0.155" upper="0.7854" velocity="2.0"/>
        <mimic joint="left_outer_knuckle_joint" multiplier="1" offset="0"/>
    </joint>
    <joint name="right_inner_knuckle_joint" type="revolute">
        <origin rpy="0 0 3.141592653589793" xyz="0 0.0165 0.0995"/>
        <parent link="grav_base_link"/>
        <child link="right_inner_bar"/>
        <axis xyz="1 0 0"/>
        <limit effort="0" lower="-0.155" upper="0.7854" velocity="2.0"/>
        <mimic joint="left_outer_knuckle_joint" multiplier="1" offset="0"/>
    </joint>
    <joint name="right_inner_finger_joint" type="revolute">      
        <origin rpy="0 0 0" xyz="0 0 0.058"/>
        <parent link="right_outer_bar"/>
        <child link="right_finger_mount"/>
        <axis xyz="1 0 0"/>
        <limit effort="0" lower="-0.7854" upper="0.155" velocity="2.0"/>
        <mimic joint="left_outer_knuckle_joint" multiplier="-1" offset="0"/>
    </joint>
    <joint name="right_inner_finger_pad_joint" type="fixed">
        <origin rpy="0 0 0" xyz="0 0.010 0.0235"/>
        <parent link="right_finger_mount"/>
        <child link="right_finger_tip"/>
        <axis xyz="0 0 1"/>
    </joint>
    <joint name="right_finger_tcp_joint" type="fixed">
        <origin rpy="0 0 0" xyz="0 0.0135 0.036"/>
        <parent link="right_finger_tip"/>
        <child link="right_finger_tcp"/>
        <axis xyz="0 0 1"/>
    </joint>

    <!-- 
    Control joint.
    Should we replace this with transmission?
    Note: This virtual joint should be prismatic, 
            but it must be revolute to match the mimic joint.
            The unused link cannot have 0 mass.
    -->
    <joint name="finger_width_joint" type="revolute">
        <origin rpy="0 0 0" xyz="0 0 0"/>
        <parent link="grav_base_link"/>
        <child link="unused_finger_width_link"/>
        <axis xyz="1 0 0"/>
        <limit effort="80" lower="0" upper="0.100" velocity="0.2"/>
    </joint>

    <link name="unused_finger_width_link">
        <inertial>
        <origin rpy="0 0 0" xyz="0 0 0"/>
        <mass value="1E-4"/>
        <inertia ixx="1E-7" ixy="0" ixz="0" iyy="1E-7" iyz="0" izz="1E-7"/>
        </inertial>
    </link>

    <!-- materials -->
    <material name="flexiv_black">
        <color rgba="0.22 0.22 0.22 1"/>
    </material>


  </xacro:macro>
</robot>
