<?xml version="1.0" ?>
<!-- =================================================================================== -->
<!-- |    This document was autogenerated by xacro from rizon.urdf.xacro               | -->
<!-- |    EDITING THIS FILE BY HAND IS NOT RECOMMENDED                                 | -->
<!-- =================================================================================== -->
<robot name="dual_rizon">
  <!-- parameters -->
  <!-- desk and robot body -->
  <link name="world">
    <!-- <visual name="body_visual">
        <origin xyz="0 0 0 " rpy="0 0 0"/>
        <geometry>
          <box size="0.3 0.23 1 "/>
        </geometry>
        <material name="rizon_light_grey" />
      </visual>
      <collision name="body_collision">
        <origin xyz="0 0 0" rpy="0 0 0"/>
        <geometry>
          <box size="0.3 0.23 1"/>
        </geometry>
      </collision>  -->
  </link>
  <material name="rizon_blue">
    <color rgba="0.0 0.0 1.0 0.5"/>
  </material>
  <material name="rizon_light_grey">
    <color rgba="0.7 0.7 0.7 1.0"/>
  </material>
  <material name="rizon_dark_grey">
    <color rgba="0.4 0.4 0.4 1.0"/>
  </material>
  <material name="rizon_white">
    <color rgba="1.0 1.0 1.0 1.0"/>
  </material>
  <material name="flexiv_black">
    <color rgba="0.22 0.22 0.22 1"/>
  </material>
  <material name="aluminum">
    <color rgba="0.5 0.5 0.5 1"/>
  </material>
  <material name="plastic">
    <color rgba="0.1 0.1 0.1 1"/>
  </material>
  <joint name="mount_jointl" type="fixed">
    <parent link="world_link_l"/>
    <child link="mount_link_l"/>
    <!-- <origin xyz="0.0 0.125 0.0" rpy="-1.57079632679 0.0 0.0"/> -->
    <origin rpy="-1.8326 0.0 0.0" xyz="0.0 0.1 0.0"/>
  </joint>
  <link name="mount_link_l"/>
  <joint name="world_jointl" type="fixed">
    <parent link="world"/>
    <child link="world_link_l"/>
    <origin rpy="0.0 0.0 0.0" xyz="0.0 0.006 0.0"/>
  </joint>
  <link name="world_link_l"/>
  <joint name="mount_jointr" type="fixed">
    <parent link="world_link_r"/>
    <child link="mount_link_r"/>
    <origin rpy="1.8326 0.0 0.0" xyz="0.0 -0.1 0.0"/>
  </joint>
  <link name="mount_link_r"/>
  <joint name="world_jointr" type="fixed">
    <parent link="world_link_l"/>
    <child link="world_link_r"/>
    <origin rpy="0.0 0.0 0.0" xyz="0.0 -0.012 0.0"/>
  </joint>
  <link name="world_link_r"/>
  <!-- 相机标定的结果,运行/home/jiaoda/wy/robot_arms/flexiv_ros_ws/src/dual_arm_robot/scripts/transform.py -->
  <!-- <joint name="mount_jointr" type="fixed">
      <parent link="mount_link_l"/>
      <child link="mount_link_r" />
      <origin rpy="-2.618447606189306 0.011019958912394816 0.002848390284717208" xyz="-0.013060362302636009 0.043699601184804426 -0.2061631332720316"/>      
    </joint>
    <link name="mount_link_r"/> -->
  <!-- 右臂 -->
  <!-- JOINTS-->
  <joint name="r_base_joint" type="fixed">
    <parent link="mount_link_r"/>
    <child link="r_base_link"/>
    <origin rpy="0.0 0.0 0.0" xyz="0.0 0.0 0.0"/>
    <!-- <origin xyz="0.0 -0.2 0.0" rpy="1.57079632679 0.0 0.0"/> -->
  </joint>
  <joint name="r_joint1" type="revolute">
    <parent link="r_base_link"/>
    <child link="r_link1"/>
    <origin rpy="3.141592653589793 0.0 -3.141592653589793" xyz="0.0 0.0 0.155"/>
    <axis xyz="0 0 1"/>
    <limit effort="123" lower="-2.7925" upper="2.7925" velocity="2.0944"/>
  </joint>
  <joint name="r_joint2" type="revolute">
    <parent link="r_link1"/>
    <child link="r_link2"/>
    <origin rpy="0.0 0.0 -3.141592653589793" xyz="0.0 0.03 -0.21"/>
    <axis xyz="0 1 0"/>
    <limit effort="123" lower="-2.2689" upper="2.2689" velocity="2.0944"/>
  </joint>
  <joint name="r_joint3" type="revolute">
    <parent link="r_link2"/>
    <child link="r_link3"/>
    <origin rpy="0.0 0.0 -3.141592653589793" xyz="0.0 -0.035 -0.205"/>
    <axis xyz="0 0 1"/>
    <limit effort="64" lower="-2.9671" upper="2.9671" velocity="2.4435"/>
  </joint>
  <joint name="r_joint4" type="revolute">
    <parent link="r_link3"/>
    <child link="r_link4"/>
    <origin rpy="0.0 0.0 0.0" xyz="-0.02 -0.03 -0.19"/>
    <axis xyz="0 1 0"/>
    <limit effort="64" lower="-1.8675" upper="2.6878" velocity="2.4435"/>
  </joint>
  <joint name="r_joint5" type="revolute">
    <parent link="r_link4"/>
    <child link="r_link5"/>
    <origin rpy="0.0 0.0 0.0" xyz="0.02 -0.025 -0.195"/>
    <axis xyz="0 0 1"/>
    <limit effort="39" lower="-2.9671" upper="2.9671" velocity="4.8869"/>
  </joint>
  <joint name="r_joint6" type="revolute">
    <parent link="r_link5"/>
    <child link="r_link6"/>
    <origin rpy="0.0 0.0 -3.141592653589793" xyz="0.0 0.03 -0.19"/>
    <axis xyz="0 1 0"/>
    <limit effort="39" lower="-1.3963" upper="4.5379" velocity="4.8869"/>
  </joint>
  <joint name="r_joint7" type="revolute">
    <parent link="r_link6"/>
    <child link="r_link7"/>
    <origin rpy="0.0 -1.5707963478683205 0.0" xyz="0.015 -0.073 -0.11"/>
    <axis xyz="0 0 1"/>
    <limit effort="39" lower="-2.9671" upper="2.9671" velocity="4.8869"/>
  </joint>
  <joint name="r_link7_to_flange" type="fixed">
    <parent link="r_link7"/>
    <child link="r_flange"/>
    <origin rpy="3.141592653589793 0.0 0.0" xyz="0.0 0.0 -0.081"/>
  </joint>
  <link name="r_base_link">
    <inertial>
      <mass value="3.7"/>
      <origin rpy="0 0 0" xyz="-0.0 0.0 0.09"/>
      <inertia ixx="0.02" ixy="0.0" ixz="0.0" iyy="0.02" iyz="-0.0" izz="0.01"/>
    </inertial>
    <visual name="shell">
      <origin rpy="0 0 3.141592653589793" xyz="0 0 0"/>
      <geometry>
        <mesh filename="package://flexiv_description/meshes/rizon4mr/visual/link0.obj"/>
      </geometry>
      <material name="rizon_light_grey"/>
    </visual>
    <collision name="hull">
      <origin rpy="0 0 3.141592653589793" xyz="0 0 0"/>
      <geometry>
        <mesh filename="package://flexiv_description/meshes/rizon4mr/collision/link0.stl"/>
      </geometry>
    </collision>
  </link>
  <link name="r_link1">
    <inertial>
      <mass value="3.7"/>
      <origin rpy="0 0 0" xyz="-0.0 0.01 -0.15"/>
      <inertia ixx="0.03" ixy="0.0" ixz="0.0" iyy="0.03" iyz="-0.0" izz="0.01"/>
    </inertial>
    <visual name="shell">
      <origin rpy="0 3.141592653589793 0" xyz="0 0 0"/>
      <geometry>
        <mesh filename="package://flexiv_description/meshes/rizon4mr/visual/link1.obj"/>
      </geometry>
      <material name="rizon_light_grey"/>
    </visual>
    <visual name="ring">
      <origin rpy="0 0 0" xyz="0 0 0.0025"/>
      <geometry>
        <mesh filename="package://flexiv_description/meshes/rizon4mr/visual/ring.obj" scale="0.062 0.062 0.002"/>
      </geometry>
      <material name="rizon_white"/>
    </visual>
    <collision name="hull">
      <origin rpy="0 3.141592653589793 0" xyz="0 0 0"/>
      <geometry>
        <mesh filename="package://flexiv_description/meshes/rizon4mr/collision/link1.stl"/>
      </geometry>
    </collision>
  </link>
  <link name="r_link2">
    <inertial>
      <mass value="2.7"/>
      <origin rpy="0 0 0" xyz="0.0 -0.04 -0.1"/>
      <inertia ixx="0.02" ixy="0.0" ixz="0.0" iyy="0.02" iyz="-0.0" izz="0.0"/>
    </inertial>
    <visual name="shell">
      <origin rpy="3.141592653589793 0 0" xyz="0 0 0"/>
      <geometry>
        <mesh filename="package://flexiv_description/meshes/rizon4mr/visual/link2.obj"/>
      </geometry>
      <material name="rizon_light_grey"/>
    </visual>
    <visual name="ring">
      <origin rpy="1.5707963 0 0" xyz="0 0.0025 0"/>
      <geometry>
        <mesh filename="package://flexiv_description/meshes/rizon4mr/visual/ring.obj" scale="0.062 0.062 0.002"/>
      </geometry>
      <material name="rizon_white"/>
    </visual>
    <collision name="hull">
      <origin rpy="3.141592653589793 0 0" xyz="0 0 0"/>
      <geometry>
        <mesh filename="package://flexiv_description/meshes/rizon4mr/collision/link2.stl"/>
      </geometry>
    </collision>
  </link>
  <link name="r_link3">
    <inertial>
      <mass value="2.4"/>
      <origin rpy="0 0 0" xyz="-0.01 -0.0 0.13"/>
      <inertia ixx="0.01" ixy="0.0" ixz="0.0" iyy="0.01" iyz="0.0" izz="0.0"/>
    </inertial>
    <visual name="shell">
      <origin rpy="0 3.141592653589793 0" xyz="0 0 0"/>
      <geometry>
        <mesh filename="package://flexiv_description/meshes/rizon4mr/visual/link3r.obj"/>
      </geometry>
      <material name="rizon_light_grey"/>
    </visual>
    <visual name="ring">
      <origin rpy="0 0 0" xyz="0 0 0.0025"/>
      <geometry>
        <mesh filename="package://flexiv_description/meshes/rizon4mr/visual/ring.obj" scale="0.051 0.051 0.002"/>
      </geometry>
      <material name="rizon_white"/>
    </visual>
    <collision name="hull">
      <origin rpy="0 3.141592653589793 0" xyz="0 0 0"/>
      <geometry>
        <mesh filename="package://flexiv_description/meshes/rizon4mr/collision/link3r.stl"/>
      </geometry>
    </collision>
  </link>
  <link name="r_link4">
    <inertial>
      <mass value="2.4"/>
      <origin rpy="0 0 0" xyz="0.01 -0.03 -0.1"/>
      <inertia ixx="0.02" ixy="0.0" ixz="-0.0" iyy="0.02" iyz="-0.0" izz="0.0"/>
    </inertial>
    <visual name="shell">
      <origin rpy="3.141592653589793 0 0" xyz="0 0 0"/>
      <geometry>
        <mesh filename="package://flexiv_description/meshes/rizon4mr/visual/link4r.obj"/>
      </geometry>
      <material name="rizon_light_grey"/>
    </visual>
    <visual name="ring">
      <origin rpy="1.5707963 0 0" xyz="0 0.0025 0"/>
      <geometry>
        <mesh filename="package://flexiv_description/meshes/rizon4mr/visual/ring.obj" scale="0.051 0.051 0.002"/>
      </geometry>
      <material name="rizon_white"/>
    </visual>
    <collision name="hull">
      <origin rpy="3.141592653589793 0 0" xyz="0 0 0"/>
      <geometry>
        <mesh filename="package://flexiv_description/meshes/rizon4mr/collision/link4r.stl"/>
      </geometry>
    </collision>
  </link>
  <link name="r_link5">
    <inertial>
      <mass value="2.4"/>
      <origin rpy="0 0 0" xyz="0.0 0.0 -0.13"/>
      <inertia ixx="0.01" ixy="0.0" ixz="0.0" iyy="0.01" iyz="-0.0" izz="0.0"/>
    </inertial>
    <visual name="shell">
      <origin rpy="0 3.141592653589793 0" xyz="0 0 0"/>
      <geometry>
        <mesh filename="package://flexiv_description/meshes/rizon4mr/visual/link5.obj"/>
      </geometry>
      <material name="rizon_light_grey"/>
    </visual>
    <visual name="ring">
      <origin rpy="0 0 0" xyz="0 0 0.0025"/>
      <geometry>
        <mesh filename="package://flexiv_description/meshes/rizon4mr/visual/ring.obj" scale="0.051 0.051 0.002"/>
      </geometry>
      <material name="rizon_white"/>
    </visual>
    <collision name="hull">
      <origin rpy="0 3.141592653589793 0" xyz="0 0 0"/>
      <geometry>
        <mesh filename="package://flexiv_description/meshes/rizon4mr/collision/link5.stl"/>
      </geometry>
    </collision>
  </link>
  <link name="r_link6">
    <inertial>
      <mass value="2.2"/>
      <origin rpy="0 0 0" xyz="-0.02 -0.06 -0.07"/>
      <inertia ixx="0.01" ixy="0.0" ixz="0.0" iyy="0.01" iyz="0.0" izz="0.0"/>
    </inertial>
    <visual name="shell">
      <origin rpy="0 3.141592653589793 0" xyz="0 0 0"/>
      <geometry>
        <mesh filename="package://flexiv_description/meshes/rizon4mr/visual/link6r.obj"/>
      </geometry>
      <material name="rizon_light_grey"/>
    </visual>
    <visual name="ring">
      <origin rpy="1.5707963 0 0" xyz="0 0.0025 0"/>
      <geometry>
        <mesh filename="package://flexiv_description/meshes/rizon4mr/visual/ring.obj" scale="0.051 0.051 0.002"/>
      </geometry>
      <material name="rizon_white"/>
    </visual>
    <collision name="hull">
      <origin rpy="0 3.141592653589793 0" xyz="0 0 0"/>
      <geometry>
        <mesh filename="package://flexiv_description/meshes/rizon4mr/collision/link6r.stl"/>
      </geometry>
    </collision>
  </link>
  <link name="r_link7">
    <inertial>
      <mass value="0.8"/>
      <origin rpy="0 0 0" xyz="0.0 -0.0 0.03"/>
      <inertia ixx="0.0" ixy="0.0" ixz="0.0" iyy="0.0" iyz="0.0" izz="0.0"/>
    </inertial>
    <visual name="shell">
      <origin rpy="3.141592653589793 0 0" xyz="0 0 0"/>
      <geometry>
        <mesh filename="package://flexiv_description/meshes/rizon4mr/visual/link7.obj"/>
      </geometry>
      <material name="rizon_light_grey"/>
    </visual>
    <visual name="ring">
      <origin rpy="0 0 0" xyz="0 0 0.0025"/>
      <geometry>
        <mesh filename="package://flexiv_description/meshes/rizon4mr/visual/ring.obj" scale="0.051 0.051 0.002"/>
      </geometry>
      <material name="rizon_white"/>
    </visual>
    <collision name="hull">
      <origin rpy="3.141592653589793 0 0" xyz="0 0 0"/>
      <geometry>
        <mesh filename="package://flexiv_description/meshes/rizon4mr/collision/link7.stl"/>
      </geometry>
    </collision>
  </link>
  <link name="r_flange"/>
  <!-- 右夹爪 -->
  <joint name="r_rizon_grav_joint" type="fixed">
    <parent link="r_flange"/>
    <child link="r_grav_base_link"/>
    <origin rpy="0 0 0.7504915783575618" xyz="0 0 0"/>
    <!--第三个数值是安装角度43度-->
  </joint>
  <!-- base link -->
  <link name="r_grav_base_link">
    <inertial>
      <origin rpy="0 0 0" xyz="0 0 0.057"/>
      <mass value="1.186"/>
      <inertia ixx="3E-3" ixy="0" ixz="0" iyy="3E-3" iyz="-0" izz="1E-3"/>
    </inertial>
    <visual>
      <origin rpy="0 0 1.5707963267948966" xyz="0 0 0"/>
      <geometry>
        <mesh filename="package://flexiv_description/meshes/grav/visual/base.stl" scale="0.001 0.001 0.001"/>
      </geometry>
      <material name="flexiv_black"/>
    </visual>
    <collision>
      <origin rpy="0 0 1.5707963267948966" xyz="0 0 0"/>
      <geometry>
        <mesh filename="package://flexiv_description/meshes/grav/collision/base.stl" scale="0.001 0.001 0.001"/>
      </geometry>
    </collision>
  </link>
  <!-- left finger links -->
  <link name="r_left_outer_bar">
    <inertial>
      <origin rpy="0 0 0" xyz="0 0 0.029"/>
      <mass value="1E-4"/>
      <inertia ixx="1E-7" ixy="0" ixz="0" iyy="1E-7" iyz="0" izz="1E-7"/>
    </inertial>
    <visual>
      <origin rpy="0 0 1.5707963267948966" xyz="0 0 0"/>
      <geometry>
        <mesh filename="package://flexiv_description/meshes/grav/visual/outer_bar.stl" scale="0.001 0.001 0.001"/>
      </geometry>
      <material name="flexiv_black"/>
    </visual>
    <collision>
      <origin rpy="0 0 0" xyz="0 0 0"/>
      <geometry>
        <box size="0.001 0.001 0.001"/>
      </geometry>
    </collision>
  </link>
  <link name="r_left_inner_bar">
    <inertial>
      <origin rpy="0 0 0" xyz="0 0 0.029"/>
      <mass value="1E-4"/>
      <inertia ixx="1E-7" ixy="0" ixz="0" iyy="1E-7" iyz="0" izz="1E-7"/>
    </inertial>
    <visual>
      <origin rpy="0 0 1.5707963267948966" xyz="0 0 0"/>
      <geometry>
        <mesh filename="package://flexiv_description/meshes/grav/visual/inner_bar.stl" scale="0.001 0.001 0.001"/>
      </geometry>
      <material name="flexiv_black"/>
    </visual>
    <collision>
      <origin rpy="0 0 0" xyz="0 0 0"/>
      <geometry>
        <box size="0.001 0.001 0.001"/>
      </geometry>
    </collision>
  </link>
  <link name="r_left_finger_mount">
    <inertial>
      <origin rpy="0 0 0" xyz="0 0 0"/>
      <mass value="1E-4"/>
      <inertia ixx="1E-7" ixy="0" ixz="0" iyy="1E-7" iyz="0" izz="1E-7"/>
    </inertial>
    <visual>
      <origin rpy="0 0 1.5707963267948966" xyz="0 0 0"/>
      <geometry>
        <mesh filename="package://flexiv_description/meshes/grav/visual/finger_mount.stl" scale="0.001 0.001 0.001"/>
      </geometry>
      <material name="flexiv_black"/>
    </visual>
    <collision>
      <origin rpy="0 0 0" xyz="0 0 0"/>
      <geometry>
        <box size="0.001 0.001 0.001"/>
      </geometry>
    </collision>
  </link>
  <link name="r_left_finger_tip">
    <inertial>
      <origin rpy="0 0 0" xyz="0 0 0"/>
      <mass value="0"/>
      <inertia ixx="0" ixy="0" ixz="0" iyy="0" iyz="0" izz="0"/>
    </inertial>
    <visual>
      <origin rpy="0 0 1.5707963267948966" xyz="0 0 0"/>
      <geometry>
        <mesh filename="package://flexiv_description/meshes/grav/visual/finger_tip.obj" scale="0.001 0.001 0.001"/>
      </geometry>
    </visual>
    <collision>
      <origin rpy="0 0 1.5707963267948966" xyz="0 0 0"/>
      <geometry>
        <mesh filename="package://flexiv_description/meshes/grav/collision/finger_tip.stl" scale="0.001 0.001 0.001"/>
      </geometry>
    </collision>
  </link>
  <!-- right finger links -->
  <link name="r_right_outer_bar">
    <inertial>
      <origin rpy="0 0 0" xyz="0 0 0.029"/>
      <mass value="1E-4"/>
      <inertia ixx="1E-7" ixy="0" ixz="0" iyy="1E-7" iyz="0" izz="1E-7"/>
    </inertial>
    <visual>
      <origin rpy="0 0 1.5707963267948966" xyz="0 0 0"/>
      <geometry>
        <mesh filename="package://flexiv_description/meshes/grav/visual/outer_bar.stl" scale="0.001 0.001 0.001"/>
      </geometry>
      <material name="flexiv_black"/>
    </visual>
    <collision>
      <origin rpy="0 0 0" xyz="0 0 0"/>
      <geometry>
        <box size="0.001 0.001 0.001"/>
      </geometry>
    </collision>
  </link>
  <link name="r_right_inner_bar">
    <inertial>
      <origin rpy="0 0 0" xyz="0 0 0.029"/>
      <mass value="1E-4"/>
      <inertia ixx="1E-7" ixy="0" ixz="0" iyy="1E-7" iyz="0" izz="1E-7"/>
    </inertial>
    <visual>
      <origin rpy="0 0 1.5707963267948966" xyz="0 0 0"/>
      <geometry>
        <mesh filename="package://flexiv_description/meshes/grav/visual/inner_bar.stl" scale="0.001 0.001 0.001"/>
      </geometry>
      <material name="flexiv_black"/>
    </visual>
    <collision>
      <origin rpy="0 0 0" xyz="0 0 0"/>
      <geometry>
        <box size="0.001 0.001 0.001"/>
      </geometry>
    </collision>
  </link>
  <link name="r_right_finger_mount">
    <inertial>
      <origin rpy="0 0 0" xyz="0 0 0"/>
      <mass value="1E-4"/>
      <inertia ixx="1E-7" ixy="0" ixz="0" iyy="1E-7" iyz="0" izz="1E-7"/>
    </inertial>
    <visual>
      <origin rpy="0 0 1.5707963267948966" xyz="0 0 0"/>
      <geometry>
        <mesh filename="package://flexiv_description/meshes/grav/visual/finger_mount.stl" scale="0.001 0.001 0.001"/>
      </geometry>
      <material name="flexiv_black"/>
    </visual>
    <collision>
      <origin rpy="0 0 0" xyz="0 0 0"/>
      <geometry>
        <box size="0.001 0.001 0.001"/>
      </geometry>
    </collision>
  </link>
  <link name="r_right_finger_tip">
    <inertial>
      <origin rpy="0 0 0" xyz="0 0 0"/>
      <mass value="0"/>
      <inertia ixx="0" ixy="0" ixz="0" iyy="0" iyz="0" izz="0"/>
    </inertial>
    <visual>
      <origin rpy="0 0 1.5707963267948966" xyz="0 0 0"/>
      <geometry>
        <mesh filename="package://flexiv_description/meshes/grav/visual/finger_tip.obj" scale="0.001 0.001 0.001"/>
      </geometry>
    </visual>
    <collision>
      <origin rpy="0 0 1.5707963267948966" xyz="0 0 0"/>
      <geometry>
        <mesh filename="package://flexiv_description/meshes/grav/collision/finger_tip.stl" scale="0.001 0.001 0.001"/>
      </geometry>
    </collision>
  </link>
  <!-- TCP links -->
  <link name="r_tcp">
    <!-- open finger, used by RCA -->
    <inertial>
      <origin rpy="0 0 0" xyz="0 0 0"/>
      <mass value="0"/>
      <inertia ixx="0" ixy="0" ixz="0" iyy="0" iyz="0" izz="0"/>
    </inertial>
  </link>
  <link name="r_closed_fingers_tcp">
    <inertial>
      <origin rpy="0 0 0" xyz="0 0 0"/>
      <mass value="0"/>
      <inertia ixx="0" ixy="0" ixz="0" iyy="0" iyz="0" izz="0"/>
    </inertial>
  </link>
  <link name="r_left_finger_tcp">
    <inertial>
      <origin rpy="0 0 0" xyz="0 0 0"/>
      <mass value="0"/>
      <inertia ixx="0" ixy="0" ixz="0" iyy="0" iyz="0" izz="0"/>
    </inertial>
  </link>
  <link name="r_right_finger_tcp">
    <inertial>
      <origin rpy="0 0 0" xyz="0 0 0"/>
      <mass value="0"/>
      <inertia ixx="0" ixy="0" ixz="0" iyy="0" iyz="0" izz="0"/>
    </inertial>
  </link>
  <joint name="r_open_fingers_tcp_joint" type="fixed">
    <origin rpy="0 0 0" xyz="0 0 0.15"/>
    <parent link="r_grav_base_link"/>
    <child link="r_tcp"/>
    <axis xyz="0 0 1"/>
  </joint>
  <joint name="r_closed_fingers_tcp_joint" type="fixed">
    <origin rpy="0 0 0" xyz="0 0 0.20"/>
    <parent link="r_grav_base_link"/>
    <child link="r_closed_fingers_tcp"/>
    <axis xyz="0 0 1"/>
  </joint>
  <!-- left finger joints -->
  <joint name="r_left_outer_knuckle_joint" type="revolute">
    <origin rpy="0 0 0" xyz="0 -0.0325 0.0825"/>
    <parent link="r_grav_base_link"/>
    <child link="r_left_outer_bar"/>
    <axis xyz="1 0 0"/>
    <limit effort="0" lower="-0.155" upper="0.7854" velocity="2.0"/>
    <mimic joint="r_finger_width_joint" multiplier="9.404" offset="-0.155"/>
  </joint>
  <joint name="r_left_inner_knuckle_joint" type="revolute">
    <origin rpy="0 0 0" xyz="0 -0.0165 0.0995"/>
    <parent link="r_grav_base_link"/>
    <child link="r_left_inner_bar"/>
    <axis xyz="1 0 0"/>
    <limit effort="0" lower="-0.155" upper="0.7854" velocity="2.0"/>
    <mimic joint="r_left_outer_knuckle_joint" multiplier="1" offset="0"/>
  </joint>
  <joint name="r_left_inner_finger_joint" type="revolute">
    <origin rpy="0 0 0" xyz="0 0 0.058"/>
    <parent link="r_left_outer_bar"/>
    <child link="r_left_finger_mount"/>
    <axis xyz="1 0 0"/>
    <limit effort="0" lower="-0.7854" upper="0.155" velocity="2.0"/>
    <mimic joint="r_left_outer_knuckle_joint" multiplier="-1" offset="0"/>
  </joint>
  <joint name="r_left_inner_finger_pad_joint" type="fixed">
    <origin rpy="0 0 0" xyz="0 0.010 0.0235"/>
    <parent link="r_left_finger_mount"/>
    <child link="r_left_finger_tip"/>
    <axis xyz="0 0 1"/>
  </joint>
  <joint name="r_left_finger_tcp_joint" type="fixed">
    <origin rpy="0 0 0" xyz="0 0.0135 0.036"/>
    <parent link="r_left_finger_tip"/>
    <child link="r_left_finger_tcp"/>
    <axis xyz="0 0 1"/>
  </joint>
  <!-- right finger joints -->
  <joint name="r_right_outer_knuckle_joint" type="revolute">
    <origin rpy="0 0 3.141592653589793" xyz="0 0.0325 0.0825"/>
    <parent link="r_grav_base_link"/>
    <child link="r_right_outer_bar"/>
    <axis xyz="1 0 0"/>
    <limit effort="0" lower="-0.155" upper="0.7854" velocity="2.0"/>
    <mimic joint="r_left_outer_knuckle_joint" multiplier="1" offset="0"/>
  </joint>
  <joint name="r_right_inner_knuckle_joint" type="revolute">
    <origin rpy="0 0 3.141592653589793" xyz="0 0.0165 0.0995"/>
    <parent link="r_grav_base_link"/>
    <child link="r_right_inner_bar"/>
    <axis xyz="1 0 0"/>
    <limit effort="0" lower="-0.155" upper="0.7854" velocity="2.0"/>
    <mimic joint="r_left_outer_knuckle_joint" multiplier="1" offset="0"/>
  </joint>
  <joint name="r_right_inner_finger_joint" type="revolute">
    <origin rpy="0 0 0" xyz="0 0 0.058"/>
    <parent link="r_right_outer_bar"/>
    <child link="r_right_finger_mount"/>
    <axis xyz="1 0 0"/>
    <limit effort="0" lower="-0.7854" upper="0.155" velocity="2.0"/>
    <mimic joint="r_left_outer_knuckle_joint" multiplier="-1" offset="0"/>
  </joint>
  <joint name="r_right_inner_finger_pad_joint" type="fixed">
    <origin rpy="0 0 0" xyz="0 0.010 0.0235"/>
    <parent link="r_right_finger_mount"/>
    <child link="r_right_finger_tip"/>
    <axis xyz="0 0 1"/>
  </joint>
  <joint name="r_right_finger_tcp_joint" type="fixed">
    <origin rpy="0 0 0" xyz="0 0.0135 0.036"/>
    <parent link="r_right_finger_tip"/>
    <child link="r_right_finger_tcp"/>
    <axis xyz="0 0 1"/>
  </joint>
  <!-- 
  Control joint.
  Should we replace this with transmission?
  Note: This virtual joint should be prismatic, 
        but it must be revolute to match the mimic joint.
        The unused link cannot have 0 mass.
  -->
  <joint name="r_finger_width_joint" type="revolute">
    <origin rpy="0 0 0" xyz="0 0 0"/>
    <parent link="r_grav_base_link"/>
    <child link="r_unused_finger_width_link"/>
    <axis xyz="1 0 0"/>
    <limit effort="80" lower="0" upper="0.100" velocity="0.2"/>
  </joint>
  <link name="r_unused_finger_width_link">
    <inertial>
      <origin rpy="0 0 0" xyz="0 0 0"/>
      <mass value="1E-4"/>
      <inertia ixx="1E-7" ixy="0" ixz="0" iyy="1E-7" iyz="0" izz="1E-7"/>
    </inertial>
  </link>
  <!-- <xacro:sensor_d435i parent="r_tcp" use_nominal_extrinsics="$(arg use_nominal_extrinsics)" >
        <origin xyz="-0.0 0.15 -0.15" rpy="0 -1.57 1.57"/>
      </xacro:sensor_d435i> -->
  <!-- 左臂 -->
  <!-- JOINTS-->
  <joint name="l_base_joint" type="fixed">
    <parent link="mount_link_l"/>
    <child link="l_base_link"/>
    <origin rpy="0.0 0.0 0.0" xyz="0.0 0.0 0.0"/>
    <!-- <origin xyz="0.0 0.2 0.0" rpy="-1.57079632679 0.0 0.0"/> -->
  </joint>
  <joint name="l_joint1" type="revolute">
    <parent link="l_base_link"/>
    <child link="l_link1"/>
    <origin rpy="0 0 -3.141592653589793" xyz="0.0 0.0 0.155"/>
    <axis xyz="0 0 1"/>
    <limit effort="123" lower="-2.7925" upper="2.7925" velocity="2.0944"/>
  </joint>
  <joint name="l_joint2" type="revolute">
    <parent link="l_link1"/>
    <child link="l_link2"/>
    <origin rpy="0 0 0" xyz="0.0 0.03 0.210"/>
    <axis xyz="0 1 0"/>
    <limit effort="123" lower="-2.2689" upper="2.2689" velocity="2.0944"/>
  </joint>
  <joint name="l_joint3" type="revolute">
    <parent link="l_link2"/>
    <child link="l_link3"/>
    <origin rpy="0 0 0" xyz="0.0 0.035 0.205"/>
    <axis xyz="0 0 1"/>
    <limit effort="64" lower="-2.9671" upper="2.9671" velocity="2.4435"/>
  </joint>
  <joint name="l_joint4" type="revolute">
    <parent link="l_link3"/>
    <child link="l_link4"/>
    <origin rpy="0 0 -3.141592653589793" xyz="-0.02 -0.03 0.19"/>
    <axis xyz="0 1 0"/>
    <limit effort="64" lower="-1.8675" upper="2.6878" velocity="2.4435"/>
  </joint>
  <joint name="l_joint5" type="revolute">
    <parent link="l_link4"/>
    <child link="l_link5"/>
    <origin rpy="0 0 -3.141592653589793" xyz="-0.02 0.025 0.195"/>
    <axis xyz="0 0 1"/>
    <limit effort="39" lower="-2.9671" upper="2.9671" velocity="4.8869"/>
  </joint>
  <joint name="l_joint6" type="revolute">
    <parent link="l_link5"/>
    <child link="l_link6"/>
    <origin rpy="0 0 0" xyz="0.0 0.03 0.19"/>
    <axis xyz="0 1 0"/>
    <limit effort="39" lower="-1.3963" upper="4.5379" velocity="4.8869"/>
  </joint>
  <joint name="l_joint7" type="revolute">
    <parent link="l_link6"/>
    <child link="l_link7"/>
    <origin rpy="0 -1.5707963267948966 0" xyz="-0.055 0.070 0.11"/>
    <axis xyz="0 0 1"/>
    <limit effort="39" lower="-2.9671" upper="2.9671" velocity="4.8869"/>
  </joint>
  <joint name="l_link7_to_flange" type="fixed">
    <parent link="l_link7"/>
    <child link="l_flange"/>
    <origin rpy="0 0 -3.141592653589793" xyz="0.0 0.0 0.081"/>
  </joint>
  <!-- LINKS -->
  <!-- <link name="world">
    </link> -->
  <link name="l_base_link">
    <inertial>
      <mass value="3.7"/>
      <origin rpy="0 0 0" xyz="0.0 -0.0 0.09"/>
      <inertia ixx="0.02" ixy="0.0" ixz="0.0" iyy="0.02" iyz="0.0" izz="0.01"/>
    </inertial>
    <visual>
      <origin rpy="0 0 0" xyz="0 0 0"/>
      <geometry>
        <mesh filename="package://flexiv_description/meshes/rizon4/visual/link0.obj"/>
      </geometry>
      <material name="rizon_light_grey"/>
    </visual>
    <collision>
      <origin rpy="0 0 0" xyz="0 0 0"/>
      <geometry>
        <mesh filename="package://flexiv_description/meshes/rizon4/collision/link0.stl"/>
      </geometry>
    </collision>
  </link>
  <link name="l_link1">
    <inertial>
      <mass value="3.7"/>
      <origin rpy="0 0 0" xyz="0.0 0.01 0.15"/>
      <inertia ixx="0.03" ixy="0.0" ixz="0.0" iyy="0.03" iyz="0.0" izz="0.01"/>
    </inertial>
    <visual>
      <origin rpy="0 0 0" xyz="0 0 0"/>
      <geometry>
        <mesh filename="package://flexiv_description/meshes/rizon4/visual/link1.obj"/>
      </geometry>
      <material name="rizon_light_grey"/>
    </visual>
    <collision>
      <origin rpy="0 0 0" xyz="0 0 0"/>
      <geometry>
        <mesh filename="package://flexiv_description/meshes/rizon4/collision/link1.stl"/>
      </geometry>
    </collision>
  </link>
  <link name="l_link2">
    <inertial>
      <mass value="2.7"/>
      <origin rpy="0 0 0" xyz="0.0 0.04 0.1"/>
      <inertia ixx="0.02" ixy="0.0" ixz="0.0" iyy="0.02" iyz="-0.0" izz="0.0"/>
    </inertial>
    <visual>
      <origin rpy="0 0 0" xyz="0 0 0"/>
      <geometry>
        <mesh filename="package://flexiv_description/meshes/rizon4/visual/link2.obj"/>
      </geometry>
      <material name="rizon_light_grey"/>
    </visual>
    <collision>
      <origin rpy="0 0 0" xyz="0 0 0"/>
      <geometry>
        <mesh filename="package://flexiv_description/meshes/rizon4/collision/link2.stl"/>
      </geometry>
    </collision>
  </link>
  <link name="l_link3">
    <inertial>
      <mass value="2.4"/>
      <origin rpy="0 0 0" xyz="-0.01 -0.0 0.13"/>
      <inertia ixx="0.01" ixy="0.0" ixz="-0.0" iyy="0.01" iyz="-0.0" izz="0.0"/>
    </inertial>
    <visual>
      <origin rpy="0 0 0" xyz="0 0 0"/>
      <geometry>
        <mesh filename="package://flexiv_description/meshes/rizon4/visual/link3.obj"/>
      </geometry>
      <material name="rizon_light_grey"/>
    </visual>
    <collision>
      <origin rpy="0 0 0" xyz="0 0 0"/>
      <geometry>
        <mesh filename="package://flexiv_description/meshes/rizon4/collision/link3.stl"/>
      </geometry>
    </collision>
  </link>
  <link name="l_link4">
    <inertial>
      <mass value="2.4"/>
      <origin rpy="0 0 0" xyz="-0.01 0.03 0.1"/>
      <inertia ixx="0.02" ixy="0.0" ixz="-0.0" iyy="0.02" iyz="-0.0" izz="0.0"/>
    </inertial>
    <visual>
      <origin rpy="0 0 0" xyz="0 0 0"/>
      <geometry>
        <mesh filename="package://flexiv_description/meshes/rizon4/visual/link4.obj"/>
      </geometry>
      <material name="rizon_light_grey"/>
    </visual>
    <collision>
      <origin rpy="0 0 0" xyz="0 0 0"/>
      <geometry>
        <mesh filename="package://flexiv_description/meshes/rizon4/collision/link4.stl"/>
      </geometry>
    </collision>
  </link>
  <link name="l_link5">
    <inertial>
      <mass value="2.4"/>
      <origin rpy="0 0 0" xyz="0.0 0.0 0.13"/>
      <inertia ixx="0.01" ixy="0.0" ixz="0.0" iyy="0.01" iyz="0.0" izz="0.0"/>
    </inertial>
    <visual>
      <origin rpy="0 0 0" xyz="0 0 0"/>
      <geometry>
        <mesh filename="package://flexiv_description/meshes/rizon4/visual/link5.obj"/>
      </geometry>
      <material name="rizon_light_grey"/>
    </visual>
    <collision>
      <origin rpy="0 0 0" xyz="0 0 0"/>
      <geometry>
        <mesh filename="package://flexiv_description/meshes/rizon4/collision/link5.stl"/>
      </geometry>
    </collision>
  </link>
  <link name="l_link6">
    <inertial>
      <mass value="2.1"/>
      <origin rpy="0 0 0" xyz="-0.01 0.06 0.07"/>
      <inertia ixx="0.01" ixy="-0.0" ixz="-0.001" iyy="0.01" iyz="0.0" izz="0.0"/>
    </inertial>
    <visual>
      <origin rpy="0 0 0" xyz="0 0 0"/>
      <geometry>
        <mesh filename="package://flexiv_description/meshes/rizon4/visual/link6.obj"/>
      </geometry>
      <material name="rizon_light_grey"/>
    </visual>
    <collision>
      <origin rpy="0 0 0" xyz="0 0 0"/>
      <geometry>
        <mesh filename="package://flexiv_description/meshes/rizon4/collision/link6.stl"/>
      </geometry>
    </collision>
  </link>
  <link name="l_link7">
    <inertial>
      <mass value="0.8"/>
      <origin rpy="0 0 0" xyz="0.0 0.0 0.03"/>
      <inertia ixx="0.0" ixy="0.0" ixz="0.0" iyy="0.0" iyz="0.0" izz="0.0"/>
    </inertial>
    <visual>
      <origin rpy="0 0 0" xyz="0 0 0"/>
      <geometry>
        <mesh filename="package://flexiv_description/meshes/rizon4/visual/link7.obj"/>
      </geometry>
      <material name="rizon_light_grey"/>
    </visual>
    <collision>
      <origin rpy="0 0 0" xyz="0 0 0"/>
      <geometry>
        <mesh filename="package://flexiv_description/meshes/rizon4/collision/link7.stl"/>
      </geometry>
    </collision>
  </link>
  <link name="l_flange"/>
  <!-- 左夹爪 -->
  <joint name="l_rizon_grav_joint" type="fixed">
    <parent link="l_flange"/>
    <child link="l_grav_base_link"/>
    <origin rpy="0 0 0" xyz="0 0 0"/>
  </joint>
  <!-- base link -->
  <link name="l_grav_base_link">
    <inertial>
      <origin rpy="0 0 0" xyz="0 0 0.057"/>
      <mass value="1.186"/>
      <inertia ixx="3E-3" ixy="0" ixz="0" iyy="3E-3" iyz="-0" izz="1E-3"/>
    </inertial>
    <visual>
      <origin rpy="0 0 1.5707963267948966" xyz="0 0 0"/>
      <geometry>
        <mesh filename="package://flexiv_description/meshes/grav/visual/base.stl" scale="0.001 0.001 0.001"/>
      </geometry>
      <material name="flexiv_black"/>
    </visual>
    <collision>
      <origin rpy="0 0 1.5707963267948966" xyz="0 0 0"/>
      <geometry>
        <mesh filename="package://flexiv_description/meshes/grav/collision/base.stl" scale="0.001 0.001 0.001"/>
      </geometry>
    </collision>
  </link>
  <!-- left finger links -->
  <link name="l_left_outer_bar">
    <inertial>
      <origin rpy="0 0 0" xyz="0 0 0.029"/>
      <mass value="1E-4"/>
      <inertia ixx="1E-7" ixy="0" ixz="0" iyy="1E-7" iyz="0" izz="1E-7"/>
    </inertial>
    <visual>
      <origin rpy="0 0 1.5707963267948966" xyz="0 0 0"/>
      <geometry>
        <mesh filename="package://flexiv_description/meshes/grav/visual/outer_bar.stl" scale="0.001 0.001 0.001"/>
      </geometry>
      <material name="flexiv_black"/>
    </visual>
    <collision>
      <origin rpy="0 0 0" xyz="0 0 0"/>
      <geometry>
        <box size="0.001 0.001 0.001"/>
      </geometry>
    </collision>
  </link>
  <link name="l_left_inner_bar">
    <inertial>
      <origin rpy="0 0 0" xyz="0 0 0.029"/>
      <mass value="1E-4"/>
      <inertia ixx="1E-7" ixy="0" ixz="0" iyy="1E-7" iyz="0" izz="1E-7"/>
    </inertial>
    <visual>
      <origin rpy="0 0 1.5707963267948966" xyz="0 0 0"/>
      <geometry>
        <mesh filename="package://flexiv_description/meshes/grav/visual/inner_bar.stl" scale="0.001 0.001 0.001"/>
      </geometry>
      <material name="flexiv_black"/>
    </visual>
    <collision>
      <origin rpy="0 0 0" xyz="0 0 0"/>
      <geometry>
        <box size="0.001 0.001 0.001"/>
      </geometry>
    </collision>
  </link>
  <link name="l_left_finger_mount">
    <inertial>
      <origin rpy="0 0 0" xyz="0 0 0"/>
      <mass value="1E-4"/>
      <inertia ixx="1E-7" ixy="0" ixz="0" iyy="1E-7" iyz="0" izz="1E-7"/>
    </inertial>
    <visual>
      <origin rpy="0 0 1.5707963267948966" xyz="0 0 0"/>
      <geometry>
        <mesh filename="package://flexiv_description/meshes/grav/visual/finger_mount.stl" scale="0.001 0.001 0.001"/>
      </geometry>
      <material name="flexiv_black"/>
    </visual>
    <collision>
      <origin rpy="0 0 0" xyz="0 0 0"/>
      <geometry>
        <box size="0.001 0.001 0.001"/>
      </geometry>
    </collision>
  </link>
  <link name="l_left_finger_tip">
    <inertial>
      <origin rpy="0 0 0" xyz="0 0 0"/>
      <mass value="0"/>
      <inertia ixx="0" ixy="0" ixz="0" iyy="0" iyz="0" izz="0"/>
    </inertial>
    <visual>
      <origin rpy="0 0 1.5707963267948966" xyz="0 0 0"/>
      <geometry>
        <mesh filename="package://flexiv_description/meshes/grav/visual/finger_tip.obj" scale="0.001 0.001 0.001"/>
      </geometry>
    </visual>
    <collision>
      <origin rpy="0 0 1.5707963267948966" xyz="0 0 0"/>
      <geometry>
        <mesh filename="package://flexiv_description/meshes/grav/collision/finger_tip.stl" scale="0.001 0.001 0.001"/>
      </geometry>
    </collision>
  </link>
  <!-- right finger links -->
  <link name="l_right_outer_bar">
    <inertial>
      <origin rpy="0 0 0" xyz="0 0 0.029"/>
      <mass value="1E-4"/>
      <inertia ixx="1E-7" ixy="0" ixz="0" iyy="1E-7" iyz="0" izz="1E-7"/>
    </inertial>
    <visual>
      <origin rpy="0 0 1.5707963267948966" xyz="0 0 0"/>
      <geometry>
        <mesh filename="package://flexiv_description/meshes/grav/visual/outer_bar.stl" scale="0.001 0.001 0.001"/>
      </geometry>
      <material name="flexiv_black"/>
    </visual>
    <collision>
      <origin rpy="0 0 0" xyz="0 0 0"/>
      <geometry>
        <box size="0.001 0.001 0.001"/>
      </geometry>
    </collision>
  </link>
  <link name="l_right_inner_bar">
    <inertial>
      <origin rpy="0 0 0" xyz="0 0 0.029"/>
      <mass value="1E-4"/>
      <inertia ixx="1E-7" ixy="0" ixz="0" iyy="1E-7" iyz="0" izz="1E-7"/>
    </inertial>
    <visual>
      <origin rpy="0 0 1.5707963267948966" xyz="0 0 0"/>
      <geometry>
        <mesh filename="package://flexiv_description/meshes/grav/visual/inner_bar.stl" scale="0.001 0.001 0.001"/>
      </geometry>
      <material name="flexiv_black"/>
    </visual>
    <collision>
      <origin rpy="0 0 0" xyz="0 0 0"/>
      <geometry>
        <box size="0.001 0.001 0.001"/>
      </geometry>
    </collision>
  </link>
  <link name="l_right_finger_mount">
    <inertial>
      <origin rpy="0 0 0" xyz="0 0 0"/>
      <mass value="1E-4"/>
      <inertia ixx="1E-7" ixy="0" ixz="0" iyy="1E-7" iyz="0" izz="1E-7"/>
    </inertial>
    <visual>
      <origin rpy="0 0 1.5707963267948966" xyz="0 0 0"/>
      <geometry>
        <mesh filename="package://flexiv_description/meshes/grav/visual/finger_mount.stl" scale="0.001 0.001 0.001"/>
      </geometry>
      <material name="flexiv_black"/>
    </visual>
    <collision>
      <origin rpy="0 0 0" xyz="0 0 0"/>
      <geometry>
        <box size="0.001 0.001 0.001"/>
      </geometry>
    </collision>
  </link>
  <link name="l_right_finger_tip">
    <inertial>
      <origin rpy="0 0 0" xyz="0 0 0"/>
      <mass value="0"/>
      <inertia ixx="0" ixy="0" ixz="0" iyy="0" iyz="0" izz="0"/>
    </inertial>
    <visual>
      <origin rpy="0 0 1.5707963267948966" xyz="0 0 0"/>
      <geometry>
        <mesh filename="package://flexiv_description/meshes/grav/visual/finger_tip.obj" scale="0.001 0.001 0.001"/>
      </geometry>
    </visual>
    <collision>
      <origin rpy="0 0 1.5707963267948966" xyz="0 0 0"/>
      <geometry>
        <mesh filename="package://flexiv_description/meshes/grav/collision/finger_tip.stl" scale="0.001 0.001 0.001"/>
      </geometry>
    </collision>
  </link>
  <!-- TCP links -->
  <link name="l_tcp">
    <!-- open finger, used by RCA -->
    <inertial>
      <origin rpy="0 0 0" xyz="0 0 0"/>
      <mass value="0"/>
      <inertia ixx="0" ixy="0" ixz="0" iyy="0" iyz="0" izz="0"/>
    </inertial>
  </link>
  <link name="l_closed_fingers_tcp">
    <inertial>
      <origin rpy="0 0 0" xyz="0 0 0"/>
      <mass value="0"/>
      <inertia ixx="0" ixy="0" ixz="0" iyy="0" iyz="0" izz="0"/>
    </inertial>
  </link>
  <link name="l_left_finger_tcp">
    <inertial>
      <origin rpy="0 0 0" xyz="0 0 0"/>
      <mass value="0"/>
      <inertia ixx="0" ixy="0" ixz="0" iyy="0" iyz="0" izz="0"/>
    </inertial>
  </link>
  <link name="l_right_finger_tcp">
    <inertial>
      <origin rpy="0 0 0" xyz="0 0 0"/>
      <mass value="0"/>
      <inertia ixx="0" ixy="0" ixz="0" iyy="0" iyz="0" izz="0"/>
    </inertial>
  </link>
  <joint name="l_open_fingers_tcp_joint" type="fixed">
    <origin rpy="0 0 0" xyz="0 0 0.15"/>
    <parent link="l_grav_base_link"/>
    <child link="l_tcp"/>
    <axis xyz="0 0 1"/>
  </joint>
  <joint name="l_closed_fingers_tcp_joint" type="fixed">
    <origin rpy="0 0 0" xyz="0 0 0.20"/>
    <parent link="l_grav_base_link"/>
    <child link="l_closed_fingers_tcp"/>
    <axis xyz="0 0 1"/>
  </joint>
  <!-- left finger joints -->
  <joint name="l_left_outer_knuckle_joint" type="revolute">
    <origin rpy="0 0 0" xyz="0 -0.0325 0.0825"/>
    <parent link="l_grav_base_link"/>
    <child link="l_left_outer_bar"/>
    <axis xyz="1 0 0"/>
    <limit effort="0" lower="-0.155" upper="0.7854" velocity="2.0"/>
    <mimic joint="l_finger_width_joint" multiplier="9.404" offset="-0.155"/>
  </joint>
  <joint name="l_left_inner_knuckle_joint" type="revolute">
    <origin rpy="0 0 0" xyz="0 -0.0165 0.0995"/>
    <parent link="l_grav_base_link"/>
    <child link="l_left_inner_bar"/>
    <axis xyz="1 0 0"/>
    <limit effort="0" lower="-0.155" upper="0.7854" velocity="2.0"/>
    <mimic joint="l_left_outer_knuckle_joint" multiplier="1" offset="0"/>
  </joint>
  <joint name="l_left_inner_finger_joint" type="revolute">
    <origin rpy="0 0 0" xyz="0 0 0.058"/>
    <parent link="l_left_outer_bar"/>
    <child link="l_left_finger_mount"/>
    <axis xyz="1 0 0"/>
    <limit effort="0" lower="-0.7854" upper="0.155" velocity="2.0"/>
    <mimic joint="l_left_outer_knuckle_joint" multiplier="-1" offset="0"/>
  </joint>
  <joint name="l_left_inner_finger_pad_joint" type="fixed">
    <origin rpy="0 0 0" xyz="0 0.010 0.0235"/>
    <parent link="l_left_finger_mount"/>
    <child link="l_left_finger_tip"/>
    <axis xyz="0 0 1"/>
  </joint>
  <joint name="l_left_finger_tcp_joint" type="fixed">
    <origin rpy="0 0 0" xyz="0 0.0135 0.036"/>
    <parent link="l_left_finger_tip"/>
    <child link="l_left_finger_tcp"/>
    <axis xyz="0 0 1"/>
  </joint>
  <!-- right finger joints -->
  <joint name="l_right_outer_knuckle_joint" type="revolute">
    <origin rpy="0 0 3.141592653589793" xyz="0 0.0325 0.0825"/>
    <parent link="l_grav_base_link"/>
    <child link="l_right_outer_bar"/>
    <axis xyz="1 0 0"/>
    <limit effort="0" lower="-0.155" upper="0.7854" velocity="2.0"/>
    <mimic joint="l_left_outer_knuckle_joint" multiplier="1" offset="0"/>
  </joint>
  <joint name="l_right_inner_knuckle_joint" type="revolute">
    <origin rpy="0 0 3.141592653589793" xyz="0 0.0165 0.0995"/>
    <parent link="l_grav_base_link"/>
    <child link="l_right_inner_bar"/>
    <axis xyz="1 0 0"/>
    <limit effort="0" lower="-0.155" upper="0.7854" velocity="2.0"/>
    <mimic joint="l_left_outer_knuckle_joint" multiplier="1" offset="0"/>
  </joint>
  <joint name="l_right_inner_finger_joint" type="revolute">
    <origin rpy="0 0 0" xyz="0 0 0.058"/>
    <parent link="l_right_outer_bar"/>
    <child link="l_right_finger_mount"/>
    <axis xyz="1 0 0"/>
    <limit effort="0" lower="-0.7854" upper="0.155" velocity="2.0"/>
    <mimic joint="l_left_outer_knuckle_joint" multiplier="-1" offset="0"/>
  </joint>
  <joint name="l_right_inner_finger_pad_joint" type="fixed">
    <origin rpy="0 0 0" xyz="0 0.010 0.0235"/>
    <parent link="l_right_finger_mount"/>
    <child link="l_right_finger_tip"/>
    <axis xyz="0 0 1"/>
  </joint>
  <joint name="l_right_finger_tcp_joint" type="fixed">
    <origin rpy="0 0 0" xyz="0 0.0135 0.036"/>
    <parent link="l_right_finger_tip"/>
    <child link="l_right_finger_tcp"/>
    <axis xyz="0 0 1"/>
  </joint>
  <!-- 
  Control joint.
  Should we replace this with transmission?
  Note: This virtual joint should be prismatic, 
        but it must be revolute to match the mimic joint.
        The unused link cannot have 0 mass.
  -->
  <joint name="l_finger_width_joint" type="revolute">
    <origin rpy="0 0 0" xyz="0 0 0"/>
    <parent link="l_grav_base_link"/>
    <child link="l_unused_finger_width_link"/>
    <axis xyz="1 0 0"/>
    <limit effort="80" lower="0" upper="0.100" velocity="0.2"/>
  </joint>
  <link name="l_unused_finger_width_link">
    <inertial>
      <origin rpy="0 0 0" xyz="0 0 0"/>
      <mass value="1E-4"/>
      <inertia ixx="1E-7" ixy="0" ixz="0" iyy="1E-7" iyz="0" izz="1E-7"/>
    </inertial>
  </link>
</robot>

