<?xml version="1.0"?>
<!-- ======================================================================== -->
<!-- | Flexiv Rizon 4 (with blurred dynamic parameters)                     | -->
<!-- ======================================================================== -->
<robot name="rizon4">

    <link name="world"/> <!--没有parent/joint, 默认为在world坐标系下的基准点(没有joint也不能运动)--> 
    <joint name="fixed_base" type="fixed">
        <parent link="world"/>
        <child link="base_link"/> <!--固定连接基座link，与world呈现fixed连接-->
        <origin rpy="0 0 0" xyz="0 0 0"/> <!-- 添加了origin元素以明确固定连接的位置和方向 -->
    </joint>

    <joint name="joint1" type="revolute">
        <parent link="base_link"/>
        <child link="link1"/>
        <origin rpy="0.0 0.0 -3.141592653589793" xyz="0.0 0.0 0.155"/>
        <axis xyz="0 0 1"/>
        <limit effort="123" lower="-2.7925" upper="2.7925" velocity="2.0944"/>
    </joint>
    <joint name="joint2" type="revolute">
        <parent link="link1"/>
        <child link="link2"/>
        <origin rpy="0.0 0.0 0.0" xyz="0.0 0.03 0.21"/>
        <axis xyz="0 1 0"/>
        <limit effort="123" lower="-2.2689" upper="2.2689" velocity="2.0944"/>
    </joint>
    <joint name="joint3" type="revolute">
        <parent link="link2"/>
        <child link="link3"/>
        <origin rpy="0.0 0.0 0.0" xyz="0.0 0.035 0.205"/>
        <axis xyz="0 0 1"/>
        <limit effort="64" lower="-2.9671" upper="2.9671" velocity="2.4435"/>
    </joint>
    <joint name="joint4" type="revolute">
        <parent link="link3"/>
        <child link="link4"/>
        <origin rpy="0.0 0.0 -3.141592653589793" xyz="-0.02 -0.03 0.19"/>
        <axis xyz="0 1 0"/>
        <limit effort="64" lower="-1.8675" upper="2.6878" velocity="2.4435"/>
    </joint>
    <joint name="joint5" type="revolute">
        <parent link="link4"/>
        <child link="link5"/>
        <origin rpy="0.0 0.0 -3.141592653589793" xyz="-0.02 0.025 0.195"/>
        <axis xyz="0 0 1"/>
        <limit effort="39" lower="-2.9671" upper="2.9671" velocity="4.8869"/>
    </joint>
    <joint name="joint6" type="revolute">
        <parent link="link5"/>
        <child link="link6"/>
        <origin rpy="0.0 0.0 0.0" xyz="0.0 0.03 0.19"/>
        <axis xyz="0 1 0"/>
        <limit effort="39" lower="-1.3963" upper="4.5379" velocity="4.8869"/>
    </joint>
    <joint name="joint7" type="revolute">
        <parent link="link6"/>
        <child link="link7"/>
        <origin rpy="0.0 -1.5707963478683205 0.0" xyz="-0.015 0.073 0.11"/>
        <axis xyz="0 0 1"/>
        <limit effort="39" lower="-2.9671" upper="2.9671" velocity="4.8869"/>
    </joint>

    <joint name="link7_to_flange" type="fixed">
        <parent link="link7"/>
        <child link="flange"/>
        <origin rpy="0.0 0.0 -3.141592653589793" xyz="0.0 0.0 0.081"/>
    </joint>

    <joint name="flange_to_flange_with_ori" type="fixed">
        <parent link="flange"/>
        <child link="flange_with_ori"/>
        <origin rpy="0.0 0.0 0.7504915783575618" xyz="0 0 0"/>
    </joint>

    <link name="flange_with_ori"/>


    <link name="base_link">
        <inertial>
            <mass value="3.7"/>
            <origin rpy="0 0 0" xyz="0.0 -0.0 0.09"/>
            <inertia ixx="0.02" ixy="0.0" ixz="0.0" iyy="0.02" iyz="0.0" izz="0.01"/>
        </inertial>
        <visual name="shell">
            <origin rpy="0 0 0" xyz="0 0 0"/>
            <geometry>
                <mesh filename="../../meshes/rizon44/visual/link0.obj"/>
            </geometry>
            <material name="rizon_light_grey"/>
        </visual>
        <collision name="hull">
            <origin rpy="0 0 0" xyz="0 0 0"/>
            <geometry>
                <mesh filename="../../meshes/rizon44/collision/link0.stl"/>
            </geometry>
        </collision>
    </link>
    <link name="link1">
        <inertial>
            <mass value="3.7"/>
            <origin rpy="0 0 0" xyz="0.0 0.01 0.15"/>
            <inertia ixx="0.03" ixy="0.0" ixz="0.0" iyy="0.03" iyz="0.0" izz="0.01"/>
        </inertial>
        <visual name="shell">
            <origin rpy="0 0 0" xyz="0 0 0"/>
            <geometry>
                <mesh filename="../../meshes/rizon44/visual/link1.obj"/>
            </geometry>
            <material name="rizon_light_grey"/>
        </visual>
        <visual name="ring">
            <origin rpy="0 0 0" xyz="0 0 -0.0025"/>
            <geometry>
                <mesh filename="../../meshes/rizon44/visual/ring.obj" scale="0.062 0.062 0.002"/>
            </geometry>
            <material name="rizon_white"/>
        </visual>
        <collision name="hull">
            <origin rpy="0 0 0" xyz="0 0 0"/>
            <geometry>
                <mesh filename="../../meshes/rizon44/collision/link1.stl"/>
            </geometry>
        </collision>
    </link>
    <link name="link2">
        <inertial>
            <mass value="2.7"/>
            <origin rpy="0 0 0" xyz="0.0 0.04 0.1"/>
            <inertia ixx="0.02" ixy="0.0" ixz="0.0" iyy="0.02" iyz="-0.0" izz="0.0"/>
        </inertial>
        <visual name="shell">
            <origin rpy="0 0 0" xyz="0 0 0"/>
            <geometry>
                <mesh filename="../../meshes/rizon44/visual/link2.obj"/>
            </geometry>
            <material name="rizon_light_grey"/>
        </visual>
        <visual name="ring">
            <origin rpy="1.5707963 0 0" xyz="0 -0.0025 0"/>
            <geometry>
                <mesh filename="../../meshes/rizon44/visual/ring.obj" scale="0.062 0.062 0.002"/>
            </geometry>
            <material name="rizon_white"/>
        </visual>
        <collision name="hull">
            <origin rpy="0 0 0" xyz="0 0 0"/>
            <geometry>
                <mesh filename="../../meshes/rizon44/collision/link2.stl"/>
            </geometry>
        </collision>
    </link>
    <link name="link3">
        <inertial>
            <mass value="2.4"/>
            <origin rpy="0 0 0" xyz="-0.01 -0.0 0.13"/>
            <inertia ixx="0.01" ixy="0.0" ixz="-0.0" iyy="0.01" iyz="-0.0" izz="0.0"/>
        </inertial>
        <visual name="shell">
            <origin rpy="0 0 0" xyz="0 0 0"/>
            <geometry>
                <mesh filename="../../meshes/rizon44/visual/link3.obj"/>
            </geometry>
            <material name="rizon_light_grey"/>
        </visual>
        <visual name="ring">
            <origin rpy="0 0 0" xyz="0 0 -0.0025"/>
            <geometry>
                <mesh filename="../../meshes/rizon44/visual/ring.obj" scale="0.051 0.051 0.002"/>
            </geometry>
            <material name="rizon_white"/>
        </visual>
        <collision name="hull">
            <origin rpy="0 0 0" xyz="0 0 0"/>
            <geometry>
                <mesh filename="../../meshes/rizon44/collision/link3.stl"/>
            </geometry>
        </collision>
    </link>
    <link name="link4">
        <inertial>
            <mass value="2.4"/>
            <origin rpy="0 0 0" xyz="-0.01 0.03 0.1"/>
            <inertia ixx="0.02" ixy="0.0" ixz="-0.0" iyy="0.02" iyz="-0.0" izz="0.0"/>
        </inertial>
        <visual name="shell">
            <origin rpy="0 0 0" xyz="0 0 0"/>
            <geometry>
                <mesh filename="../../meshes/rizon44/visual/link4.obj"/>
            </geometry>
            <material name="rizon_light_grey"/>
        </visual>
        <visual name="ring">
            <origin rpy="1.5707963 0 0" xyz="0 -0.0025 0"/>
            <geometry>
                <mesh filename="../../meshes/rizon44/visual/ring.obj" scale="0.051 0.051 0.002"/>
            </geometry>
            <material name="rizon_white"/>
        </visual>
        <collision name="hull">
            <origin rpy="0 0 0" xyz="0 0 0"/>
            <geometry>
                <mesh filename="../../meshes/rizon44/collision/link4.stl"/>
            </geometry>
        </collision>
    </link>
    <link name="link5">
        <inertial>
            <mass value="2.4"/>
            <origin rpy="0 0 0" xyz="-0.0 0.0 0.13"/>
            <inertia ixx="0.01" ixy="0.0" ixz="0.0" iyy="0.01" iyz="0.0" izz="0.0"/>
        </inertial>
        <visual name="shell">
            <origin rpy="0 0 0" xyz="0 0 0"/>
            <geometry>
                <mesh filename="../../meshes/rizon44/visual/link5.obj"/>
            </geometry>
            <material name="rizon_light_grey"/>
        </visual>
        <visual name="ring">
            <origin rpy="0 0 0" xyz="0 0 -0.0025"/>
            <geometry>
                <mesh filename="../../meshes/rizon44/visual/ring.obj" scale="0.051 0.051 0.002"/>
            </geometry>
            <material name="rizon_white"/>
        </visual>
        <collision name="hull">
            <origin rpy="0 0 0" xyz="0 0 0"/>
            <geometry>
                <mesh filename="../../meshes/rizon44/collision/link5.stl"/>
            </geometry>
        </collision>
    </link>
    <link name="link6">
        <inertial>
            <mass value="2.2"/>
            <origin rpy="0 0 0" xyz="0.02 0.06 0.07"/>
            <inertia ixx="0.01" ixy="0.0" ixz="0.0" iyy="0.01" iyz="0.0" izz="0.0"/>
        </inertial>
        <visual name="shell">
            <origin rpy="0 0 0" xyz="0 0 0"/>
            <geometry>
                <mesh filename="../../meshes/rizon44/visual/link6.obj"/>
            </geometry>
            <material name="rizon_light_grey"/>
        </visual>
        <visual name="ring">
            <origin rpy="1.5707963 0 0" xyz="0 -0.0025 0"/>
            <geometry>
                <mesh filename="../../meshes/rizon44/visual/ring.obj" scale="0.051 0.051 0.002"/>
            </geometry>
            <material name="rizon_white"/>
        </visual>
        <collision name="hull">
            <origin rpy="0 0 0" xyz="0 0 0"/>
            <geometry>
                <mesh filename="../../meshes/rizon44/collision/link6.stl"/>
            </geometry>
        </collision>
    </link>
    <link name="link7">
        <inertial>
            <mass value="0.8"/>
            <origin rpy="0 0 0" xyz="0.0 -0.0 0.03"/>
            <inertia ixx="0.0" ixy="0.0" ixz="0.0" iyy="0.0" iyz="0.0" izz="0.0"/>
        </inertial>
        <visual name="shell">
            <origin rpy="0 0 0" xyz="0 0 0"/>
            <geometry>
                <mesh filename="../../meshes/rizon44/visual/link7.obj"/>
            </geometry>
            <material name="rizon_light_grey"/>
        </visual>
        <visual name="ring">
            <origin rpy="0 0 0" xyz="0 0 -0.0025"/>
            <geometry>
                <mesh filename="../../meshes/rizon44/visual/ring.obj" scale="0.051 0.051 0.002"/>
            </geometry>
            <material name="rizon_white"/>
        </visual>
        <collision name="hull">
            <origin rpy="0 0 0" xyz="0 0 0"/>
            <geometry>
                <mesh filename="../../meshes/rizon44/collision/link7.stl"/>
            </geometry>
        </collision>
    </link>
    <link name="flange"/>

     <!-- 夹爪 -->
    <joint name="rizon_grav_joint" type="fixed">
        <parent link="flange"/>
        <child link="grav_base_link"/>
        <origin rpy="0 0 0.7504915783575618" xyz="0 0 0"/>
        <!--第三个数值是安装角度43度-->
    </joint>

    <!-- base link -->
    <link name="grav_base_link">
        <inertial>
        <origin rpy="0 0 0" xyz="0 0 0.057"/>
        <mass value="1.186"/>
        <inertia ixx="3E-3" ixy="0" ixz="0" iyy="3E-3" iyz="-0" izz="1E-3"/>
        </inertial>
        <visual>
            <origin rpy="0 0 1.5707963267948966" xyz="0 0 0"/>
            <geometry>
                <mesh filename="../../meshes/grav/visual/base.stl" scale="0.001 0.001 0.001"/>
            </geometry>
            <material name="flexiv_black"/>
        </visual>
        <collision>
            <origin rpy="0 0 1.5707963267948966" xyz="0 0 0"/>
            <geometry>
                <mesh filename="../../meshes/grav/collision/base.stl" scale="0.001 0.001 0.001"/>
            </geometry>
        </collision>
    </link>

  <!-- left finger links -->
  <link name="left_outer_bar">
    <inertial>
      <origin rpy="0 0 0" xyz="0 0 0.029"/>
      <mass value="1E-4"/>
      <inertia ixx="1E-7" ixy="0" ixz="0" iyy="1E-7" iyz="0" izz="1E-7"/>
    </inertial>
    <visual>
      <origin rpy="0 0 1.5707963267948966" xyz="0 0 0"/>
      <geometry>
        <mesh filename="../../meshes/grav/visual/outer_bar.stl" scale="0.001 0.001 0.001"/>
      </geometry>
      <material name="flexiv_black"/>
    </visual>
    <collision>
      <origin rpy="0 0 0" xyz="0 0 0"/>
      <geometry>
        <box size="0.001 0.001 0.001"/>
      </geometry>
    </collision>
  </link>
  
  <link name="left_inner_bar">
    <inertial>
      <origin rpy="0 0 0" xyz="0 0 0.029"/>
      <mass value="1E-4"/>
      <inertia ixx="1E-7" ixy="0" ixz="0" iyy="1E-7" iyz="0" izz="1E-7"/>
    </inertial>
    <visual>
      <origin rpy="0 0 1.5707963267948966" xyz="0 0 0"/>
      <geometry>
        <mesh filename="../../meshes/grav/visual/inner_bar.stl" scale="0.001 0.001 0.001"/>
      </geometry>
      <material name="flexiv_black"/>
    </visual>
    <collision>
      <origin rpy="0 0 0" xyz="0 0 0"/>
      <geometry>
        <box size="0.001 0.001 0.001"/>
      </geometry>
    </collision>
  </link>

  <link name="left_finger_mount">
    <inertial>
      <origin rpy="0 0 0" xyz="0 0 0"/>
      <mass value="1E-4"/>
      <inertia ixx="1E-7" ixy="0" ixz="0" iyy="1E-7" iyz="0" izz="1E-7"/>
    </inertial>
    <visual>
      <origin rpy="0 0 1.5707963267948966" xyz="0 0 0"/>
      <geometry>
        <mesh filename="../../meshes/grav/visual/finger_mount.stl" scale="0.001 0.001 0.001"/>
      </geometry>
      <material name="flexiv_black"/>
    </visual>
    <collision>
      <origin rpy="0 0 0" xyz="0 0 0"/>
      <geometry>
        <box size="0.001 0.001 0.001"/>
      </geometry>
    </collision>
  </link>

  <link name="left_finger_tip">
    <inertial>
      <origin rpy="0 0 0" xyz="0 0 0"/>
      <mass value="0"/>
      <inertia ixx="0" ixy="0" ixz="0" iyy="0" iyz="0" izz="0"/>
    </inertial>
    <visual>
      <origin rpy="0 0 1.5707963267948966" xyz="0 0 0"/>
      <geometry>
        <mesh filename="../../meshes/grav/visual/finger_tip.obj" scale="0.001 0.001 0.001"/>
      </geometry>
    </visual>
    <collision>
      <origin rpy="0 0 1.5707963267948966" xyz="0 0 0"/>
      <geometry>
        <mesh filename="../../meshes/grav/collision/finger_tip.stl" scale="0.001 0.001 0.001"/>
      </geometry>
    </collision>
  </link>
  <!-- right finger links -->
  <link name="right_outer_bar">
    <inertial>
      <origin rpy="0 0 0" xyz="0 0 0.029"/>
      <mass value="1E-4"/>
      <inertia ixx="1E-7" ixy="0" ixz="0" iyy="1E-7" iyz="0" izz="1E-7"/>
    </inertial>
    <visual>
      <origin rpy="0 0 1.5707963267948966" xyz="0 0 0"/>
      <geometry>
        <mesh filename="../../meshes/grav/visual/outer_bar.stl" scale="0.001 0.001 0.001"/>
      </geometry>
      <material name="flexiv_black"/>
    </visual>
    <collision>
      <origin rpy="0 0 0" xyz="0 0 0"/>
      <geometry>
        <box size="0.001 0.001 0.001"/>
      </geometry>
    </collision>
  </link>

  <link name="right_inner_bar">
    <inertial>
      <origin rpy="0 0 0" xyz="0 0 0.029"/>
      <mass value="1E-4"/>
      <inertia ixx="1E-7" ixy="0" ixz="0" iyy="1E-7" iyz="0" izz="1E-7"/>
    </inertial>
    <visual>
      <origin rpy="0 0 1.5707963267948966" xyz="0 0 0"/>
      <geometry>
        <mesh filename="../../meshes/grav/visual/inner_bar.stl" scale="0.001 0.001 0.001"/>
      </geometry>
      <material name="flexiv_black"/>
    </visual>
    <collision>
      <origin rpy="0 0 0" xyz="0 0 0"/>
      <geometry>
        <box size="0.001 0.001 0.001"/>
      </geometry>
    </collision>
  </link>

  <link name="right_finger_mount">
    <inertial>
      <origin rpy="0 0 0" xyz="0 0 0"/>
      <mass value="1E-4"/>
      <inertia ixx="1E-7" ixy="0" ixz="0" iyy="1E-7" iyz="0" izz="1E-7"/>
    </inertial>
    <visual>
      <origin rpy="0 0 1.5707963267948966" xyz="0 0 0"/>
      <geometry>
        <mesh filename="../../meshes/grav/visual/finger_mount.stl" scale="0.001 0.001 0.001"/>
      </geometry>
      <material name="flexiv_black"/>
    </visual>
    <collision>
      <origin rpy="0 0 0" xyz="0 0 0"/>
      <geometry>
        <box size="0.001 0.001 0.001"/>
      </geometry>
    </collision>
  </link>

  <link name="right_finger_tip">
    <inertial>
      <origin rpy="0 0 0" xyz="0 0 0"/>
      <mass value="0"/>
      <inertia ixx="0" ixy="0" ixz="0" iyy="0" iyz="0" izz="0"/>
    </inertial>
    <visual>
      <origin rpy="0 0 1.5707963267948966" xyz="0 0 0"/>
      <geometry>
        <mesh filename="../../meshes/grav/visual/finger_tip.obj" scale="0.001 0.001 0.001"/>
      </geometry>
    </visual>
    <collision>
      <origin rpy="0 0 1.5707963267948966" xyz="0 0 0"/>
      <geometry>
        <mesh filename="../../meshes/grav/collision/finger_tip.stl" scale="0.001 0.001 0.001"/>
      </geometry>
    </collision>
  </link>

  <!-- TCP links -->
  <link name="tcp">
    <!-- open finger, used by RCA -->
    <inertial>
      <origin rpy="0 0 0" xyz="0 0 0"/>
      <mass value="0"/>
      <inertia ixx="0" ixy="0" ixz="0" iyy="0" iyz="0" izz="0"/>
    </inertial>
  </link>

  <link name="closed_fingers_tcp">
    <inertial>
      <origin rpy="0 0 0" xyz="0 0 0"/>
      <mass value="0"/>
      <inertia ixx="0" ixy="0" ixz="0" iyy="0" iyz="0" izz="0"/>
    </inertial>
  </link>
  <link name="left_finger_tcp">
    <inertial>
      <origin rpy="0 0 0" xyz="0 0 0"/>
      <mass value="0"/>
      <inertia ixx="0" ixy="0" ixz="0" iyy="0" iyz="0" izz="0"/>
    </inertial>
  </link>
  <link name="right_finger_tcp">
    <inertial>
      <origin rpy="0 0 0" xyz="0 0 0"/>
      <mass value="0"/>
      <inertia ixx="0" ixy="0" ixz="0" iyy="0" iyz="0" izz="0"/>
    </inertial>
  </link>

  <joint name="open_fingers_tcp_joint" type="fixed">
    <origin rpy="0 0 0" xyz="0 0 0.15"/>
    <parent link="grav_base_link"/>
    <child link="tcp"/>
    <axis xyz="0 0 1"/>
  </joint>
  <joint name="closed_fingers_tcp_joint" type="fixed">
    <origin rpy="0 0 0" xyz="0 0 0.20"/>
    <parent link="grav_base_link"/>
    <child link="closed_fingers_tcp"/>
    <axis xyz="0 0 1"/>
  </joint>

  <!-- left finger joints -->
  <joint name="left_outer_knuckle_joint" type="revolute">
    <origin rpy="0 0 0" xyz="0 -0.0325 0.0825"/>
    <parent link="grav_base_link"/>
    <child link="left_outer_bar"/>
    <axis xyz="1 0 0"/>
    <limit effort="0" lower="-0.155" upper="0.7854" velocity="2.0"/>
    <mimic joint="finger_width_joint" multiplier="9.404" offset="-0.155"/>
  </joint>

  <joint name="left_inner_knuckle_joint" type="revolute">
    <origin rpy="0 0 0" xyz="0 -0.0165 0.0995"/>
    <parent link="grav_base_link"/>
    <child link="left_inner_bar"/>
    <axis xyz="1 0 0"/>
    <limit effort="0" lower="-0.155" upper="0.7854" velocity="2.0"/>
    <mimic joint="left_outer_knuckle_joint" multiplier="1" offset="0"/>
  </joint>

  <joint name="left_inner_finger_joint" type="revolute">
    <origin rpy="0 0 0" xyz="0 0 0.058"/>
    <parent link="left_outer_bar"/>
    <child link="left_finger_mount"/>
    <axis xyz="1 0 0"/>
    <limit effort="0" lower="-0.7854" upper="0.155" velocity="2.0"/>
    <mimic joint="left_outer_knuckle_joint" multiplier="-1" offset="0"/>
  </joint>

  <joint name="left_inner_finger_pad_joint" type="fixed">
    <origin rpy="0 0 0" xyz="0 0.010 0.0235"/>
    <parent link="left_finger_mount"/>
    <child link="left_finger_tip"/>
    <axis xyz="0 0 1"/>
  </joint>

  <joint name="left_finger_tcp_joint" type="fixed">
    <origin rpy="0 0 0" xyz="0 0.0135 0.036"/>
    <parent link="left_finger_tip"/>
    <child link="left_finger_tcp"/>
    <axis xyz="0 0 1"/>
  </joint>

  <!-- right finger joints -->
  <joint name="right_outer_knuckle_joint" type="revolute">
    <origin rpy="0 0 3.141592653589793" xyz="0 0.0325 0.0825"/>
    <parent link="grav_base_link"/>
    <child link="right_outer_bar"/>
    <axis xyz="1 0 0"/>
    <limit effort="0" lower="-0.155" upper="0.7854" velocity="2.0"/>
    <mimic joint="left_outer_knuckle_joint" multiplier="1" offset="0"/>
  </joint>

  <joint name="right_inner_knuckle_joint" type="revolute">
    <origin rpy="0 0 3.141592653589793" xyz="0 0.0165 0.0995"/>
    <parent link="grav_base_link"/>
    <child link="right_inner_bar"/>
    <axis xyz="1 0 0"/>
    <limit effort="0" lower="-0.155" upper="0.7854" velocity="2.0"/>
    <mimic joint="left_outer_knuckle_joint" multiplier="1" offset="0"/>
  </joint>

  <joint name="right_inner_finger_joint" type="revolute">
    <origin rpy="0 0 0" xyz="0 0 0.058"/>
    <parent link="right_outer_bar"/>
    <child link="right_finger_mount"/>
    <axis xyz="1 0 0"/>
    <limit effort="0" lower="-0.7854" upper="0.155" velocity="2.0"/>
    <mimic joint="left_outer_knuckle_joint" multiplier="-1" offset="0"/>
  </joint>

  <joint name="right_inner_finger_pad_joint" type="fixed">
    <origin rpy="0 0 0" xyz="0 0.010 0.0235"/>
    <parent link="right_finger_mount"/>
    <child link="right_finger_tip"/>
    <axis xyz="0 0 1"/>
  </joint>

  <joint name="right_finger_tcp_joint" type="fixed">
    <origin rpy="0 0 0" xyz="0 0.0135 0.036"/>
    <parent link="right_finger_tip"/>
    <child link="right_finger_tcp"/>
    <axis xyz="0 0 1"/>
  </joint>

  <!-- 
  Control joint.
  Should we replace this with transmission?
  Note: This virtual joint should be prismatic, 
        but it must be revolute to match the mimic joint.
        The unused link cannot have 0 mass.
        只是用来作为辅助控制变量，其他力矩可以在这个虚拟节点不受限
  -->
  <joint name="finger_width_joint" type="revolute">
    <origin rpy="0 0 0" xyz="0 0 0"/>
    <parent link="grav_base_link"/>
    <child link="unused_finger_width_link"/>
    <axis xyz="1 0 0"/>
    <limit effort="80" lower="0" upper="0.100" velocity="0.2"/>
  </joint>

  <link name="unused_finger_width_link">
    <inertial>
      <origin rpy="0 0 0" xyz="0 0 0"/>
      <mass value="1E-4"/>
      <inertia ixx="1E-7" ixy="0" ixz="0" iyy="1E-7" iyz="0" izz="1E-7"/>
    </inertial>
  </link>

    <material name="rizon_light_grey">
        <color rgba="0.7 0.7 0.7 1.0"/>
    </material>
    <material name="rizon_dark_grey">
        <color rgba="0.4 0.4 0.4 1.0"/>
    </material>
    <material name="rizon_white">
        <color rgba="1.0 1.0 1.0 1.0"/>
    </material>

    <material name="flexiv_black">
        <color rgba="0.22 0.22 0.22 1"/>
    </material>
</robot>